Workbook

Sheet T0_1
A1: Серия экспериментов\статистика | B1: x_ср [м.е.] | C1: Σ((Δxi)^2) [м.е.^2] | D1: σ [м.е.] | E1: x_ср+3*σ [м.е.] | F1: x_ср-3*σ [м.е.] | G1: kв [%] | H1: σ0 [м.е.] | I1: Δx [м.е.] | J1: δx [%] | K1: N_мин | L1: x_ист [м.е.]
A3: 1 | B3: 3418 | C3: 3480 | D3: =POWER(C3/($O$5-1),0.5) -> 10.954451 | E3: =B3+3*D3 -> 3450.8634 | F3: =B3-3*D3 -> 3385.1366 | G3: =D3/B3*100 -> 0.32049301 | H3: =D3/POWER($O$5, 0.5) -> 2 | I3: =H3*$P$5 -> 4 | J3: =I3/B3*100 -> 0.1170275 | K3: =ROUNDUP(POWER(G3*$P$5/$Q$5,2),0) -> 1 | L3: =B3 & " ± " & (ROUNDUP(I3, 3)) -> 3418 ± 4
A4: =A3+1 -> 2 | D4: =POWER(C4/($O$5-1),0.5) -> 0 | E4: =B4+3*D4 -> 0 | F4: =B4-3*D4 -> 0 | G4: =D4/B4*100 -> #DIV/0! | H4: =D4/POWER($O$5, 0.5) -> 0 | I4: =H4*$P$5 -> 0 | J4: =I4/B4*100 -> #DIV/0! | K4: =ROUNDUP(POWER(G4*$P$5/$Q$5,2),0) -> #DIV/0! | L4: =B4 & " ± " & (ROUNDUP(I4, 3)) -> ± 0 | N4: p | O4: N | P4: t_pN | Q4: Δ [%]
A5: =A4+1 -> 3 | D5: =POWER(C5/($O$5-1),0.5) -> 0 | E5: =B5+3*D5 -> 0 | F5: =B5-3*D5 -> 0 | G5: =D5/B5*100 -> #DIV/0! | H5: =D5/POWER($O$5, 0.5) -> 0 | I5: =H5*$P$5 -> 0 | J5: =I5/B5*100 -> #DIV/0! | K5: =ROUNDUP(POWER(G5*$P$5/$Q$5,2),0) -> #DIV/0! | L5: =B5 & " ± " & (ROUNDUP(I5, 3)) -> ± 0 | N5: 0.95 | O5: 30 | P5: 2 | Q5: 5
A6: =A5+1 -> 4 | D6: =POWER(C6/($O$5-1),0.5) -> 0 | E6: =B6+3*D6 -> 0 | F6: =B6-3*D6 -> 0 | G6: =D6/B6*100 -> #DIV/0! | H6: =D6/POWER($O$5, 0.5) -> 0 | I6: =H6*$P$5 -> 0 | J6: =I6/B6*100 -> #DIV/0! | K6: =ROUNDUP(POWER(G6*$P$5/$Q$5,2),0) -> #DIV/0! | L6: =B6 & " ± " & (ROUNDUP(I6, 3)) -> ± 0 | O6: 10 | P6: 2.77
A7: =A6+1 -> 5 | D7: =POWER(C7/($O$5-1),0.5) -> 0 | E7: =B7+3*D7 -> 0 | F7: =B7-3*D7 -> 0 | G7: =D7/B7*100 -> #DIV/0! | H7: =D7/POWER($O$5, 0.5) -> 0 | I7: =H7*$P$5 -> 0 | J7: =I7/B7*100 -> #DIV/0! | K7: =ROUNDUP(POWER(G7*$P$5/$Q$5,2),0) -> #DIV/0! | L7: =B7 & " ± " & (ROUNDUP(I7, 3)) -> ± 0 | O7: 30 | P7: 2
A8: =A7+1 -> 6 | B8: 3410 | C8: 29400 | D8: =POWER(C8/($O$5-1),0.5) -> 31.840118 | E8: =B8+3*D8 -> 3505.5204 | F8: =B8-3*D8 -> 3314.4796 | G8: =D8/B8*100 -> 0.9337278 | H8: =D8/POWER($O$5, 0.5) -> 5.8131836 | I8: =H8*$P$5 -> 11.626367 | J8: =I8/B8*100 -> 0.34094918 | K8: =ROUNDUP(POWER(G8*$P$5/$Q$5,2),0) -> 1 | L8: =B8 & " ± " & (ROUNDUP(I8, 3)) -> 3410 ± 11,627
A9: =A8+1 -> 7 | D9: =POWER(C9/($O$5-1),0.5) -> 0 | E9: =B9+3*D9 -> 0 | F9: =B9-3*D9 -> 0 | G9: =D9/B9*100 -> #DIV/0! | H9: =D9/POWER($O$5, 0.5) -> 0 | I9: =H9*$P$5 -> 0 | J9: =I9/B9*100 -> #DIV/0! | K9: =ROUNDUP(POWER(G9*$P$5/$Q$5,2),0) -> #DIV/0! | L9: =B9 & " ± " & (ROUNDUP(I9, 3)) -> ± 0
A10: =A9+1 -> 8 | D10: =POWER(C10/($O$5-1),0.5) -> 0 | E10: =B10+3*D10 -> 0 | F10: =B10-3*D10 -> 0 | G10: =D10/B10*100 -> #DIV/0! | H10: =D10/POWER($O$5, 0.5) -> 0 | I10: =H10*$P$5 -> 0 | J10: =I10/B10*100 -> #DIV/0! | K10: =ROUNDUP(POWER(G10*$P$5/$Q$5,2),0) -> #DIV/0! | L10: =B10 & " ± " & (ROUNDUP(I10, 3)) -> ± 0
A11: =A10+1 -> 9 | D11: =POWER(C11/($O$5-1),0.5) -> 0 | E11: =B11+3*D11 -> 0 | F11: =B11-3*D11 -> 0 | G11: =D11/B11*100 -> #DIV/0! | H11: =D11/POWER($O$5, 0.5) -> 0 | I11: =H11*$P$5 -> 0 | J11: =I11/B11*100 -> #DIV/0! | K11: =ROUNDUP(POWER(G11*$P$5/$Q$5,2),0) -> #DIV/0! | L11: =B11 & " ± " & (ROUNDUP(I11, 3)) -> ± 0
A12: =A11+1 -> 10 | D12: =POWER(C12/($O$5-1),0.5) -> 0 | E12: =B12+3*D12 -> 0 | F12: =B12-3*D12 -> 0 | G12: =D12/B12*100 -> #DIV/0! | H12: =D12/POWER($O$5, 0.5) -> 0 | I12: =H12*$P$5 -> 0 | J12: =I12/B12*100 -> #DIV/0! | K12: =ROUNDUP(POWER(G12*$P$5/$Q$5,2),0) -> #DIV/0! | L12: =B12 & " ± " & (ROUNDUP(I12, 3)) -> ± 0
A13: =A12+1 -> 11 | B13: 3416 | C13: 13920 | D13: =POWER(C13/($O$5-1),0.5) -> 21.908902 | E13: =B13+3*D13 -> 3481.7267 | F13: =B13-3*D13 -> 3350.2733 | G13: =D13/B13*100 -> 0.64136131 | H13: =D13/POWER($O$5, 0.5) -> 4 | I13: =H13*$P$5 -> 8 | J13: =I13/B13*100 -> 0.23419204 | K13: =ROUNDUP(POWER(G13*$P$5/$Q$5,2),0) -> 1 | L13: =B13 & " ± " & (ROUNDUP(I13, 3)) -> 3416 ± 8
A14: =A13+1 -> 12 | D14: =POWER(C14/($O$5-1),0.5) -> 0 | E14: =B14+3*D14 -> 0 | F14: =B14-3*D14 -> 0 | G14: =D14/B14*100 -> #DIV/0! | H14: =D14/POWER($O$5, 0.5) -> 0 | I14: =H14*$P$5 -> 0 | J14: =I14/B14*100 -> #DIV/0! | K14: =ROUNDUP(POWER(G14*$P$5/$Q$5,2),0) -> #DIV/0! | L14: =B14 & " ± " & (ROUNDUP(I14, 3)) -> ± 0
A15: =A14+1 -> 13 | D15: =POWER(C15/($O$5-1),0.5) -> 0 | E15: =B15+3*D15 -> 0 | F15: =B15-3*D15 -> 0 | G15: =D15/B15*100 -> #DIV/0! | H15: =D15/POWER($O$5, 0.5) -> 0 | I15: =H15*$P$5 -> 0 | J15: =I15/B15*100 -> #DIV/0! | K15: =ROUNDUP(POWER(G15*$P$5/$Q$5,2),0) -> #DIV/0! | L15: =B15 & " ± " & (ROUNDUP(I15, 3)) -> ± 0
A16: =A15+1 -> 14 | D16: =POWER(C16/($O$5-1),0.5) -> 0 | E16: =B16+3*D16 -> 0 | F16: =B16-3*D16 -> 0 | G16: =D16/B16*100 -> #DIV/0! | H16: =D16/POWER($O$5, 0.5) -> 0 | I16: =H16*$P$5 -> 0 | J16: =I16/B16*100 -> #DIV/0! | K16: =ROUNDUP(POWER(G16*$P$5/$Q$5,2),0) -> #DIV/0! | L16: =B16 & " ± " & (ROUNDUP(I16, 3)) -> ± 0
A17: =A16+1 -> 15 | D17: =POWER(C17/($O$5-1),0.5) -> 0 | E17: =B17+3*D17 -> 0 | F17: =B17-3*D17 -> 0 | G17: =D17/B17*100 -> #DIV/0! | H17: =D17/POWER($O$5, 0.5) -> 0 | I17: =H17*$P$5 -> 0 | J17: =I17/B17*100 -> #DIV/0! | K17: =ROUNDUP(POWER(G17*$P$5/$Q$5,2),0) -> #DIV/0! | L17: =B17 & " ± " & (ROUNDUP(I17, 3)) -> ± 0
A18: =A17+1 -> 16 | B18: 3312 | C18: 146880 | D18: =POWER(C18/($O$5-1),0.5) -> 71.167602 | E18: =B18+3*D18 -> 3525.5028 | F18: =B18-3*D18 -> 3098.4972 | G18: =D18/B18*100 -> 2.1487803 | H18: =D18/POWER($O$5, 0.5) -> 12.993367 | I18: =H18*$P$5 -> 25.986734 | J18: =I18/B18*100 -> 0.78462361 | K18: =ROUNDUP(POWER(G18*$P$5/$Q$5,2),0) -> 1 | L18: =B18 & " ± " & (ROUNDUP(I18, 3)) -> 3312 ± 25,987
A19: =A18+1 -> 17 | D19: =POWER(C19/($O$5-1),0.5) -> 0 | E19: =B19+3*D19 -> 0 | F19: =B19-3*D19 -> 0 | G19: =D19/B19*100 -> #DIV/0! | H19: =D19/POWER($O$5, 0.5) -> 0 | I19: =H19*$P$5 -> 0 | J19: =I19/B19*100 -> #DIV/0! | K19: =ROUNDUP(POWER(G19*$P$5/$Q$5,2),0) -> #DIV/0! | L19: =B19 & " ± " & (ROUNDUP(I19, 3)) -> ± 0
A20: =A19+1 -> 18 | D20: =POWER(C20/($O$5-1),0.5) -> 0 | E20: =B20+3*D20 -> 0 | F20: =B20-3*D20 -> 0 | G20: =D20/B20*100 -> #DIV/0! | H20: =D20/POWER($O$5, 0.5) -> 0 | I20: =H20*$P$5 -> 0 | J20: =I20/B20*100 -> #DIV/0! | K20: =ROUNDUP(POWER(G20*$P$5/$Q$5,2),0) -> #DIV/0! | L20: =B20 & " ± " & (ROUNDUP(I20, 3)) -> ± 0
A21: =A20+1 -> 19 | D21: =POWER(C21/($O$5-1),0.5) -> 0 | E21: =B21+3*D21 -> 0 | F21: =B21-3*D21 -> 0 | G21: =D21/B21*100 -> #DIV/0! | H21: =D21/POWER($O$5, 0.5) -> 0 | I21: =H21*$P$5 -> 0 | J21: =I21/B21*100 -> #DIV/0! | K21: =ROUNDUP(POWER(G21*$P$5/$Q$5,2),0) -> #DIV/0! | L21: =B21 & " ± " & (ROUNDUP(I21, 3)) -> ± 0
A22: =A21+1 -> 20 | D22: =POWER(C22/($O$5-1),0.5) -> 0 | E22: =B22+3*D22 -> 0 | F22: =B22-3*D22 -> 0 | G22: =D22/B22*100 -> #DIV/0! | H22: =D22/POWER($O$5, 0.5) -> 0 | I22: =H22*$P$5 -> 0 | J22: =I22/B22*100 -> #DIV/0! | K22: =ROUNDUP(POWER(G22*$P$5/$Q$5,2),0) -> #DIV/0! | L22: =B22 & " ± " & (ROUNDUP(I22, 3)) -> ± 0
A23: =A22+1 -> 21 | B23: 3386 | C23: 62520 | D23: =POWER(C23/($O$5-1),0.5) -> 46.431262 | E23: =B23+3*D23 -> 3525.2938 | F23: =B23-3*D23 -> 3246.7062 | G23: =D23/B23*100 -> 1.3712718 | H23: =D23/POWER($O$5, 0.5) -> 8.4771498 | I23: =H23*$P$5 -> 16.9543 | J23: =I23/B23*100 -> 0.50071765 | K23: =ROUNDUP(POWER(G23*$P$5/$Q$5,2),0) -> 1 | L23: =B23 & " ± " & (ROUNDUP(I23, 3)) -> 3386 ± 16,955
A24: =A23+1 -> 22 | D24: =POWER(C24/($O$5-1),0.5) -> 0 | E24: =B24+3*D24 -> 0 | F24: =B24-3*D24 -> 0 | G24: =D24/B24*100 -> #DIV/0! | H24: =D24/POWER($O$5, 0.5) -> 0 | I24: =H24*$P$5 -> 0 | J24: =I24/B24*100 -> #DIV/0! | K24: =ROUNDUP(POWER(G24*$P$5/$Q$5,2),0) -> #DIV/0! | L24: =B24 & " ± " & (ROUNDUP(I24, 3)) -> ± 0
A25: =A24+1 -> 23 | D25: =POWER(C25/($O$5-1),0.5) -> 0 | E25: =B25+3*D25 -> 0 | F25: =B25-3*D25 -> 0 | G25: =D25/B25*100 -> #DIV/0! | H25: =D25/POWER($O$5, 0.5) -> 0 | I25: =H25*$P$5 -> 0 | J25: =I25/B25*100 -> #DIV/0! | K25: =ROUNDUP(POWER(G25*$P$5/$Q$5,2),0) -> #DIV/0! | L25: =B25 & " ± " & (ROUNDUP(I25, 3)) -> ± 0
A26: =A25+1 -> 24 | D26: =POWER(C26/($O$5-1),0.5) -> 0 | E26: =B26+3*D26 -> 0 | F26: =B26-3*D26 -> 0 | G26: =D26/B26*100 -> #DIV/0! | H26: =D26/POWER($O$5, 0.5) -> 0 | I26: =H26*$P$5 -> 0 | J26: =I26/B26*100 -> #DIV/0! | K26: =ROUNDUP(POWER(G26*$P$5/$Q$5,2),0) -> #DIV/0! | L26: =B26 & " ± " & (ROUNDUP(I26, 3)) -> ± 0
A27: =A26+1 -> 25 | D27: =POWER(C27/($O$5-1),0.5) -> 0 | E27: =B27+3*D27 -> 0 | F27: =B27-3*D27 -> 0 | G27: =D27/B27*100 -> #DIV/0! | H27: =D27/POWER($O$5, 0.5) -> 0 | I27: =H27*$P$5 -> 0 | J27: =I27/B27*100 -> #DIV/0! | K27: =ROUNDUP(POWER(G27*$P$5/$Q$5,2),0) -> #DIV/0! | L27: =B27 & " ± " & (ROUNDUP(I27, 3)) -> ± 0
A28: =A27+1 -> 26 | B28: 2982 | C28: 1433880 | D28: =POWER(C28/($O$5-1),0.5) -> 222.36038 | E28: =B28+3*D28 -> 3649.0811 | F28: =B28-3*D28 -> 2314.9189 | G28: =D28/B28*100 -> 7.4567531 | H28: =D28/POWER($O$5, 0.5) -> 40.597265 | I28: =H28*$P$5 -> 81.19453 | J28: =I28/B28*100 -> 2.7228213 | K28: =ROUNDUP(POWER(G28*$P$5/$Q$5,2),0) -> 9 | L28: =B28 & " ± " & (ROUNDUP(I28, 3)) -> 2982 ± 81,195
A29: =A28+1 -> 27 | D29: =POWER(C29/($O$5-1),0.5) -> 0 | E29: =B29+3*D29 -> 0 | F29: =B29-3*D29 -> 0 | G29: =D29/B29*100 -> #DIV/0! | H29: =D29/POWER($O$5, 0.5) -> 0 | I29: =H29*$P$5 -> 0 | J29: =I29/B29*100 -> #DIV/0! | K29: =ROUNDUP(POWER(G29*$P$5/$Q$5,2),0) -> #DIV/0! | L29: =B29 & " ± " & (ROUNDUP(I29, 3)) -> ± 0
A30: =A29+1 -> 28 | D30: =POWER(C30/($O$5-1),0.5) -> 0 | E30: =B30+3*D30 -> 0 | F30: =B30-3*D30 -> 0 | G30: =D30/B30*100 -> #DIV/0! | H30: =D30/POWER($O$5, 0.5) -> 0 | I30: =H30*$P$5 -> 0 | J30: =I30/B30*100 -> #DIV/0! | K30: =ROUNDUP(POWER(G30*$P$5/$Q$5,2),0) -> #DIV/0! | L30: =B30 & " ± " & (ROUNDUP(I30, 3)) -> ± 0
A31: =A30+1 -> 29 | D31: =POWER(C31/($O$5-1),0.5) -> 0 | E31: =B31+3*D31 -> 0 | F31: =B31-3*D31 -> 0 | G31: =D31/B31*100 -> #DIV/0! | H31: =D31/POWER($O$5, 0.5) -> 0 | I31: =H31*$P$5 -> 0 | J31: =I31/B31*100 -> #DIV/0! | K31: =ROUNDUP(POWER(G31*$P$5/$Q$5,2),0) -> #DIV/0! | L31: =B31 & " ± " & (ROUNDUP(I31, 3)) -> ± 0
A32: =A31+1 -> 30 | D32: =POWER(C32/($O$5-1),0.5) -> 0 | E32: =B32+3*D32 -> 0 | F32: =B32-3*D32 -> 0 | G32: =D32/B32*100 -> #DIV/0! | H32: =D32/POWER($O$5, 0.5) -> 0 | I32: =H32*$P$5 -> 0 | J32: =I32/B32*100 -> #DIV/0! | K32: =ROUNDUP(POWER(G32*$P$5/$Q$5,2),0) -> #DIV/0! | L32: =B32 & " ± " & (ROUNDUP(I32, 3)) -> ± 0
A33: =A32+1 -> 31 | B33: 3356 | C33: 78720 | D33: =POWER(C33/($O$5-1),0.5) -> 52.100698 | E33: =B33+3*D33 -> 3512.3021 | F33: =B33-3*D33 -> 3199.6979 | G33: =D33/B33*100 -> 1.5524642 | H33: =D33/POWER($O$5, 0.5) -> 9.5122426 | I33: =H33*$P$5 -> 19.024485 | J33: =I33/B33*100 -> 0.56687977 | K33: =ROUNDUP(POWER(G33*$P$5/$Q$5,2),0) -> 1 | L33: =B33 & " ± " & (ROUNDUP(I33, 3)) -> 3356 ± 19,025
A34: =A33+1 -> 32 | D34: =POWER(C34/($O$5-1),0.5) -> 0 | E34: =B34+3*D34 -> 0 | F34: =B34-3*D34 -> 0 | G34: =D34/B34*100 -> #DIV/0! | H34: =D34/POWER($O$5, 0.5) -> 0 | I34: =H34*$P$5 -> 0 | J34: =I34/B34*100 -> #DIV/0! | K34: =ROUNDUP(POWER(G34*$P$5/$Q$5,2),0) -> #DIV/0! | L34: =B34 & " ± " & (ROUNDUP(I34, 3)) -> ± 0
A35: =A34+1 -> 33 | D35: =POWER(C35/($O$5-1),0.5) -> 0 | E35: =B35+3*D35 -> 0 | F35: =B35-3*D35 -> 0 | G35: =D35/B35*100 -> #DIV/0! | H35: =D35/POWER($O$5, 0.5) -> 0 | I35: =H35*$P$5 -> 0 | J35: =I35/B35*100 -> #DIV/0! | K35: =ROUNDUP(POWER(G35*$P$5/$Q$5,2),0) -> #DIV/0! | L35: =B35 & " ± " & (ROUNDUP(I35, 3)) -> ± 0
A36: =A35+1 -> 34 | D36: =POWER(C36/($O$5-1),0.5) -> 0 | E36: =B36+3*D36 -> 0 | F36: =B36-3*D36 -> 0 | G36: =D36/B36*100 -> #DIV/0! | H36: =D36/POWER($O$5, 0.5) -> 0 | I36: =H36*$P$5 -> 0 | J36: =I36/B36*100 -> #DIV/0! | K36: =ROUNDUP(POWER(G36*$P$5/$Q$5,2),0) -> #DIV/0! | L36: =B36 & " ± " & (ROUNDUP(I36, 3)) -> ± 0
A37: =A36+1 -> 35 | D37: =POWER(C37/($O$5-1),0.5) -> 0 | E37: =B37+3*D37 -> 0 | F37: =B37-3*D37 -> 0 | G37: =D37/B37*100 -> #DIV/0! | H37: =D37/POWER($O$5, 0.5) -> 0 | I37: =H37*$P$5 -> 0 | J37: =I37/B37*100 -> #DIV/0! | K37: =ROUNDUP(POWER(G37*$P$5/$Q$5,2),0) -> #DIV/0! | L37: =B37 & " ± " & (ROUNDUP(I37, 3)) -> ± 0
A38: =A37+1 -> 36 | B38: 3346 | C38: 69720 | D38: =POWER(C38/($O$5-1),0.5) -> 49.032009 | E38: =B38+3*D38 -> 3493.096 | F38: =B38-3*D38 -> 3198.904 | G38: =D38/B38*100 -> 1.4653918 | H38: =D38/POWER($O$5, 0.5) -> 8.9519792 | I38: =H38*$P$5 -> 17.903958 | J38: =I38/B38*100 -> 0.53508543 | K38: =ROUNDUP(POWER(G38*$P$5/$Q$5,2),0) -> 1 | L38: =B38 & " ± " & (ROUNDUP(I38, 3)) -> 3346 ± 17,904
A39: =A38+1 -> 37 | D39: =POWER(C39/($O$5-1),0.5) -> 0 | E39: =B39+3*D39 -> 0 | F39: =B39-3*D39 -> 0 | G39: =D39/B39*100 -> #DIV/0! | H39: =D39/POWER($O$5, 0.5) -> 0 | I39: =H39*$P$5 -> 0 | J39: =I39/B39*100 -> #DIV/0! | K39: =ROUNDUP(POWER(G39*$P$5/$Q$5,2),0) -> #DIV/0! | L39: =B39 & " ± " & (ROUNDUP(I39, 3)) -> ± 0
A40: =A39+1 -> 38 | D40: =POWER(C40/($O$5-1),0.5) -> 0 | E40: =B40+3*D40 -> 0 | F40: =B40-3*D40 -> 0 | G40: =D40/B40*100 -> #DIV/0! | H40: =D40/POWER($O$5, 0.5) -> 0 | I40: =H40*$P$5 -> 0 | J40: =I40/B40*100 -> #DIV/0! | K40: =ROUNDUP(POWER(G40*$P$5/$Q$5,2),0) -> #DIV/0! | L40: =B40 & " ± " & (ROUNDUP(I40, 3)) -> ± 0
A41: =A40+1 -> 39 | D41: =POWER(C41/($O$5-1),0.5) -> 0 | E41: =B41+3*D41 -> 0 | F41: =B41-3*D41 -> 0 | G41: =D41/B41*100 -> #DIV/0! | H41: =D41/POWER($O$5, 0.5) -> 0 | I41: =H41*$P$5 -> 0 | J41: =I41/B41*100 -> #DIV/0! | K41: =ROUNDUP(POWER(G41*$P$5/$Q$5,2),0) -> #DIV/0! | L41: =B41 & " ± " & (ROUNDUP(I41, 3)) -> ± 0
...

Sheet T0_12
A1: Серия экспериментов\статистика | B1: x_ср [м.е.] | C1: Σ((Δxi)^2) [м.е.^2] | D1: σ [м.е.] | E1: x_ср+3*σ [м.е.] | F1: x_ср-3*σ [м.е.] | G1: kв [%] | H1: σ0 [м.е.] | I1: Δx [м.е.] | J1: δx [%] | K1: N_мин | L1: x_ист [м.е.]
A3: 1 | B3: 3418 | C3: 3480 | D3: =POWER(C3/($O$5-1),0.5) -> 10.954451 | E3: =B3+3*D3 -> 3450.8634 | F3: =B3-3*D3 -> 3385.1366 | G3: =D3/B3*100 -> 0.32049301 | H3: =D3/POWER($O$5, 0.5) -> 2 | I3: =H3*$P$5 -> 4 | J3: =I3/B3*100 -> 0.1170275 | K3: =ROUNDUP(POWER(G3*$P$5/$Q$5,2),0) -> 1 | L3: =B3 & " ± " & (ROUNDUP(I3, 3)) -> 3418 ± 4
A4: =A3+1 -> 2 | D4: =POWER(C4/($O$5-1),0.5) -> 0 | E4: =B4+3*D4 -> 0 | F4: =B4-3*D4 -> 0 | G4: =D4/B4*100 -> #DIV/0! | H4: =D4/POWER($O$5, 0.5) -> 0 | I4: =H4*$P$5 -> 0 | J4: =I4/B4*100 -> #DIV/0! | K4: =ROUNDUP(POWER(G4*$P$5/$Q$5,2),0) -> #DIV/0! | L4: =B4 & " ± " & (ROUNDUP(I4, 3)) -> ± 0 | N4: p | O4: N | P4: t_pN | Q4: Δ [%]
A5: =A4+1 -> 3 | D5: =POWER(C5/($O$5-1),0.5) -> 0 | E5: =B5+3*D5 -> 0 | F5: =B5-3*D5 -> 0 | G5: =D5/B5*100 -> #DIV/0! | H5: =D5/POWER($O$5, 0.5) -> 0 | I5: =H5*$P$5 -> 0 | J5: =I5/B5*100 -> #DIV/0! | K5: =ROUNDUP(POWER(G5*$P$5/$Q$5,2),0) -> #DIV/0! | L5: =B5 & " ± " & (ROUNDUP(I5, 3)) -> ± 0 | N5: 0.95 | O5: 30 | P5: 2 | Q5: 5
A6: =A5+1 -> 4 | D6: =POWER(C6/($O$5-1),0.5) -> 0 | E6: =B6+3*D6 -> 0 | F6: =B6-3*D6 -> 0 | G6: =D6/B6*100 -> #DIV/0! | H6: =D6/POWER($O$5, 0.5) -> 0 | I6: =H6*$P$5 -> 0 | J6: =I6/B6*100 -> #DIV/0! | K6: =ROUNDUP(POWER(G6*$P$5/$Q$5,2),0) -> #DIV/0! | L6: =B6 & " ± " & (ROUNDUP(I6, 3)) -> ± 0
A7: =A6+1 -> 5 | D7: =POWER(C7/($O$5-1),0.5) -> 0 | E7: =B7+3*D7 -> 0 | F7: =B7-3*D7 -> 0 | G7: =D7/B7*100 -> #DIV/0! | H7: =D7/POWER($O$5, 0.5) -> 0 | I7: =H7*$P$5 -> 0 | J7: =I7/B7*100 -> #DIV/0! | K7: =ROUNDUP(POWER(G7*$P$5/$Q$5,2),0) -> #DIV/0! | L7: =B7 & " ± " & (ROUNDUP(I7, 3)) -> ± 0
A8: =A7+1 -> 6 | B8: 3412 | C8: 26880 | D8: =POWER(C8/($O$5-1),0.5) -> 30.444976 | E8: =B8+3*D8 -> 3503.3349 | F8: =B8-3*D8 -> 3320.6651 | G8: =D8/B8*100 -> 0.8922912 | H8: =D8/POWER($O$5, 0.5) -> 5.5584667 | I8: =H8*$P$5 -> 11.116933 | J8: =I8/B8*100 -> 0.32581868 | K8: =ROUNDUP(POWER(G8*$P$5/$Q$5,2),0) -> 1 | L8: =B8 & " ± " & (ROUNDUP(I8, 3)) -> 3412 ± 11,117
A9: =A8+1 -> 7 | D9: =POWER(C9/($O$5-1),0.5) -> 0 | E9: =B9+3*D9 -> 0 | F9: =B9-3*D9 -> 0 | G9: =D9/B9*100 -> #DIV/0! | H9: =D9/POWER($O$5, 0.5) -> 0 | I9: =H9*$P$5 -> 0 | J9: =I9/B9*100 -> #DIV/0! | K9: =ROUNDUP(POWER(G9*$P$5/$Q$5,2),0) -> #DIV/0! | L9: =B9 & " ± " & (ROUNDUP(I9, 3)) -> ± 0
A10: =A9+1 -> 8 | D10: =POWER(C10/($O$5-1),0.5) -> 0 | E10: =B10+3*D10 -> 0 | F10: =B10-3*D10 -> 0 | G10: =D10/B10*100 -> #DIV/0! | H10: =D10/POWER($O$5, 0.5) -> 0 | I10: =H10*$P$5 -> 0 | J10: =I10/B10*100 -> #DIV/0! | K10: =ROUNDUP(POWER(G10*$P$5/$Q$5,2),0) -> #DIV/0! | L10: =B10 & " ± " & (ROUNDUP(I10, 3)) -> ± 0
A11: =A10+1 -> 9 | D11: =POWER(C11/($O$5-1),0.5) -> 0 | E11: =B11+3*D11 -> 0 | F11: =B11-3*D11 -> 0 | G11: =D11/B11*100 -> #DIV/0! | H11: =D11/POWER($O$5, 0.5) -> 0 | I11: =H11*$P$5 -> 0 | J11: =I11/B11*100 -> #DIV/0! | K11: =ROUNDUP(POWER(G11*$P$5/$Q$5,2),0) -> #DIV/0! | L11: =B11 & " ± " & (ROUNDUP(I11, 3)) -> ± 0
A12: =A11+1 -> 10 | D12: =POWER(C12/($O$5-1),0.5) -> 0 | E12: =B12+3*D12 -> 0 | F12: =B12-3*D12 -> 0 | G12: =D12/B12*100 -> #DIV/0! | H12: =D12/POWER($O$5, 0.5) -> 0 | I12: =H12*$P$5 -> 0 | J12: =I12/B12*100 -> #DIV/0! | K12: =ROUNDUP(POWER(G12*$P$5/$Q$5,2),0) -> #DIV/0! | L12: =B12 & " ± " & (ROUNDUP(I12, 3)) -> ± 0
A13: =A12+1 -> 11 | B13: 3416 | C13: 13920 | D13: =POWER(C13/($O$5-1),0.5) -> 21.908902 | E13: =B13+3*D13 -> 3481.7267 | F13: =B13-3*D13 -> 3350.2733 | G13: =D13/B13*100 -> 0.64136131 | H13: =D13/POWER($O$5, 0.5) -> 4 | I13: =H13*$P$5 -> 8 | J13: =I13/B13*100 -> 0.23419204 | K13: =ROUNDUP(POWER(G13*$P$5/$Q$5,2),0) -> 1 | L13: =B13 & " ± " & (ROUNDUP(I13, 3)) -> 3416 ± 8
A14: =A13+1 -> 12 | D14: =POWER(C14/($O$5-1),0.5) -> 0 | E14: =B14+3*D14 -> 0 | F14: =B14-3*D14 -> 0 | G14: =D14/B14*100 -> #DIV/0! | H14: =D14/POWER($O$5, 0.5) -> 0 | I14: =H14*$P$5 -> 0 | J14: =I14/B14*100 -> #DIV/0! | K14: =ROUNDUP(POWER(G14*$P$5/$Q$5,2),0) -> #DIV/0! | L14: =B14 & " ± " & (ROUNDUP(I14, 3)) -> ± 0
A15: =A14+1 -> 13 | D15: =POWER(C15/($O$5-1),0.5) -> 0 | E15: =B15+3*D15 -> 0 | F15: =B15-3*D15 -> 0 | G15: =D15/B15*100 -> #DIV/0! | H15: =D15/POWER($O$5, 0.5) -> 0 | I15: =H15*$P$5 -> 0 | J15: =I15/B15*100 -> #DIV/0! | K15: =ROUNDUP(POWER(G15*$P$5/$Q$5,2),0) -> #DIV/0! | L15: =B15 & " ± " & (ROUNDUP(I15, 3)) -> ± 0
A16: =A15+1 -> 14 | D16: =POWER(C16/($O$5-1),0.5) -> 0 | E16: =B16+3*D16 -> 0 | F16: =B16-3*D16 -> 0 | G16: =D16/B16*100 -> #DIV/0! | H16: =D16/POWER($O$5, 0.5) -> 0 | I16: =H16*$P$5 -> 0 | J16: =I16/B16*100 -> #DIV/0! | K16: =ROUNDUP(POWER(G16*$P$5/$Q$5,2),0) -> #DIV/0! | L16: =B16 & " ± " & (ROUNDUP(I16, 3)) -> ± 0
A17: =A16+1 -> 15 | D17: =POWER(C17/($O$5-1),0.5) -> 0 | E17: =B17+3*D17 -> 0 | F17: =B17-3*D17 -> 0 | G17: =D17/B17*100 -> #DIV/0! | H17: =D17/POWER($O$5, 0.5) -> 0 | I17: =H17*$P$5 -> 0 | J17: =I17/B17*100 -> #DIV/0! | K17: =ROUNDUP(POWER(G17*$P$5/$Q$5,2),0) -> #DIV/0! | L17: =B17 & " ± " & (ROUNDUP(I17, 3)) -> ± 0
A18: =A17+1 -> 16 | B18: 3380 | C18: 74400 | D18: =POWER(C18/($O$5-1),0.5) -> 50.650935 | E18: =B18+3*D18 -> 3531.9528 | F18: =B18-3*D18 -> 3228.0472 | G18: =D18/B18*100 -> 1.4985484 | H18: =D18/POWER($O$5, 0.5) -> 9.2475533 | I18: =H18*$P$5 -> 18.495107 | J18: =I18/B18*100 -> 0.5471925 | K18: =ROUNDUP(POWER(G18*$P$5/$Q$5,2),0) -> 1 | L18: =B18 & " ± " & (ROUNDUP(I18, 3)) -> 3380 ± 18,496
A19: =A18+1 -> 17 | D19: =POWER(C19/($O$5-1),0.5) -> 0 | E19: =B19+3*D19 -> 0 | F19: =B19-3*D19 -> 0 | G19: =D19/B19*100 -> #DIV/0! | H19: =D19/POWER($O$5, 0.5) -> 0 | I19: =H19*$P$5 -> 0 | J19: =I19/B19*100 -> #DIV/0! | K19: =ROUNDUP(POWER(G19*$P$5/$Q$5,2),0) -> #DIV/0! | L19: =B19 & " ± " & (ROUNDUP(I19, 3)) -> ± 0
A20: =A19+1 -> 18 | D20: =POWER(C20/($O$5-1),0.5) -> 0 | E20: =B20+3*D20 -> 0 | F20: =B20-3*D20 -> 0 | G20: =D20/B20*100 -> #DIV/0! | H20: =D20/POWER($O$5, 0.5) -> 0 | I20: =H20*$P$5 -> 0 | J20: =I20/B20*100 -> #DIV/0! | K20: =ROUNDUP(POWER(G20*$P$5/$Q$5,2),0) -> #DIV/0! | L20: =B20 & " ± " & (ROUNDUP(I20, 3)) -> ± 0
A21: =A20+1 -> 19 | D21: =POWER(C21/($O$5-1),0.5) -> 0 | E21: =B21+3*D21 -> 0 | F21: =B21-3*D21 -> 0 | G21: =D21/B21*100 -> #DIV/0! | H21: =D21/POWER($O$5, 0.5) -> 0 | I21: =H21*$P$5 -> 0 | J21: =I21/B21*100 -> #DIV/0! | K21: =ROUNDUP(POWER(G21*$P$5/$Q$5,2),0) -> #DIV/0! | L21: =B21 & " ± " & (ROUNDUP(I21, 3)) -> ± 0
A22: =A21+1 -> 20 | D22: =POWER(C22/($O$5-1),0.5) -> 0 | E22: =B22+3*D22 -> 0 | F22: =B22-3*D22 -> 0 | G22: =D22/B22*100 -> #DIV/0! | H22: =D22/POWER($O$5, 0.5) -> 0 | I22: =H22*$P$5 -> 0 | J22: =I22/B22*100 -> #DIV/0! | K22: =ROUNDUP(POWER(G22*$P$5/$Q$5,2),0) -> #DIV/0! | L22: =B22 & " ± " & (ROUNDUP(I22, 3)) -> ± 0
A23: =A22+1 -> 21 | B23: 3406 | C23: 26520 | D23: =POWER(C23/($O$5-1),0.5) -> 30.240416 | E23: =B23+3*D23 -> 3496.7212 | F23: =B23-3*D23 -> 3315.2788 | G23: =D23/B23*100 -> 0.88785719 | H23: =D23/POWER($O$5, 0.5) -> 5.5211193 | I23: =H23*$P$5 -> 11.042239 | J23: =I23/B23*100 -> 0.32419961 | K23: =ROUNDUP(POWER(G23*$P$5/$Q$5,2),0) -> 1 | L23: =B23 & " ± " & (ROUNDUP(I23, 3)) -> 3406 ± 11,043
A24: =A23+1 -> 22 | D24: =POWER(C24/($O$5-1),0.5) -> 0 | E24: =B24+3*D24 -> 0 | F24: =B24-3*D24 -> 0 | G24: =D24/B24*100 -> #DIV/0! | H24: =D24/POWER($O$5, 0.5) -> 0 | I24: =H24*$P$5 -> 0 | J24: =I24/B24*100 -> #DIV/0! | K24: =ROUNDUP(POWER(G24*$P$5/$Q$5,2),0) -> #DIV/0! | L24: =B24 & " ± " & (ROUNDUP(I24, 3)) -> ± 0
A25: =A24+1 -> 23 | D25: =POWER(C25/($O$5-1),0.5) -> 0 | E25: =B25+3*D25 -> 0 | F25: =B25-3*D25 -> 0 | G25: =D25/B25*100 -> #DIV/0! | H25: =D25/POWER($O$5, 0.5) -> 0 | I25: =H25*$P$5 -> 0 | J25: =I25/B25*100 -> #DIV/0! | K25: =ROUNDUP(POWER(G25*$P$5/$Q$5,2),0) -> #DIV/0! | L25: =B25 & " ± " & (ROUNDUP(I25, 3)) -> ± 0
A26: =A25+1 -> 24 | D26: =POWER(C26/($O$5-1),0.5) -> 0 | E26: =B26+3*D26 -> 0 | F26: =B26-3*D26 -> 0 | G26: =D26/B26*100 -> #DIV/0! | H26: =D26/POWER($O$5, 0.5) -> 0 | I26: =H26*$P$5 -> 0 | J26: =I26/B26*100 -> #DIV/0! | K26: =ROUNDUP(POWER(G26*$P$5/$Q$5,2),0) -> #DIV/0! | L26: =B26 & " ± " & (ROUNDUP(I26, 3)) -> ± 0
A27: =A26+1 -> 25 | D27: =POWER(C27/($O$5-1),0.5) -> 0 | E27: =B27+3*D27 -> 0 | F27: =B27-3*D27 -> 0 | G27: =D27/B27*100 -> #DIV/0! | H27: =D27/POWER($O$5, 0.5) -> 0 | I27: =H27*$P$5 -> 0 | J27: =I27/B27*100 -> #DIV/0! | K27: =ROUNDUP(POWER(G27*$P$5/$Q$5,2),0) -> #DIV/0! | L27: =B27 & " ± " & (ROUNDUP(I27, 3)) -> ± 0
A28: =A27+1 -> 26 | B28: 3214 | C28: 840120 | D28: =POWER(C28/($O$5-1),0.5) -> 170.20474 | E28: =B28+3*D28 -> 3724.6142 | F28: =B28-3*D28 -> 2703.3858 | G28: =D28/B28*100 -> 5.2957295 | H28: =D28/POWER($O$5, 0.5) -> 31.074993 | I28: =H28*$P$5 -> 62.149985 | J28: =I28/B28*100 -> 1.933727 | K28: =ROUNDUP(POWER(G28*$P$5/$Q$5,2),0) -> 5 | L28: =B28 & " ± " & (ROUNDUP(I28, 3)) -> 3214 ± 62,15
A29: =A28+1 -> 27 | D29: =POWER(C29/($O$5-1),0.5) -> 0 | E29: =B29+3*D29 -> 0 | F29: =B29-3*D29 -> 0 | G29: =D29/B29*100 -> #DIV/0! | H29: =D29/POWER($O$5, 0.5) -> 0 | I29: =H29*$P$5 -> 0 | J29: =I29/B29*100 -> #DIV/0! | K29: =ROUNDUP(POWER(G29*$P$5/$Q$5,2),0) -> #DIV/0! | L29: =B29 & " ± " & (ROUNDUP(I29, 3)) -> ± 0
A30: =A29+1 -> 28 | D30: =POWER(C30/($O$5-1),0.5) -> 0 | E30: =B30+3*D30 -> 0 | F30: =B30-3*D30 -> 0 | G30: =D30/B30*100 -> #DIV/0! | H30: =D30/POWER($O$5, 0.5) -> 0 | I30: =H30*$P$5 -> 0 | J30: =I30/B30*100 -> #DIV/0! | K30: =ROUNDUP(POWER(G30*$P$5/$Q$5,2),0) -> #DIV/0! | L30: =B30 & " ± " & (ROUNDUP(I30, 3)) -> ± 0
A31: =A30+1 -> 29 | D31: =POWER(C31/($O$5-1),0.5) -> 0 | E31: =B31+3*D31 -> 0 | F31: =B31-3*D31 -> 0 | G31: =D31/B31*100 -> #DIV/0! | H31: =D31/POWER($O$5, 0.5) -> 0 | I31: =H31*$P$5 -> 0 | J31: =I31/B31*100 -> #DIV/0! | K31: =ROUNDUP(POWER(G31*$P$5/$Q$5,2),0) -> #DIV/0! | L31: =B31 & " ± " & (ROUNDUP(I31, 3)) -> ± 0
A32: =A31+1 -> 30 | D32: =POWER(C32/($O$5-1),0.5) -> 0 | E32: =B32+3*D32 -> 0 | F32: =B32-3*D32 -> 0 | G32: =D32/B32*100 -> #DIV/0! | H32: =D32/POWER($O$5, 0.5) -> 0 | I32: =H32*$P$5 -> 0 | J32: =I32/B32*100 -> #DIV/0! | K32: =ROUNDUP(POWER(G32*$P$5/$Q$5,2),0) -> #DIV/0! | L32: =B32 & " ± " & (ROUNDUP(I32, 3)) -> ± 0
A33: =A32+1 -> 31 | B33: 3390 | C33: 63000 | D33: =POWER(C33/($O$5-1),0.5) -> 46.60916 | E33: =B33+3*D33 -> 3529.8275 | F33: =B33-3*D33 -> 3250.1725 | G33: =D33/B33*100 -> 1.3749015 | H33: =D33/POWER($O$5, 0.5) -> 8.5096294 | I33: =H33*$P$5 -> 17.019259 | J33: =I33/B33*100 -> 0.50204303 | K33: =ROUNDUP(POWER(G33*$P$5/$Q$5,2),0) -> 1 | L33: =B33 & " ± " & (ROUNDUP(I33, 3)) -> 3390 ± 17,02
A34: =A33+1 -> 32 | D34: =POWER(C34/($O$5-1),0.5) -> 0 | E34: =B34+3*D34 -> 0 | F34: =B34-3*D34 -> 0 | G34: =D34/B34*100 -> #DIV/0! | H34: =D34/POWER($O$5, 0.5) -> 0 | I34: =H34*$P$5 -> 0 | J34: =I34/B34*100 -> #DIV/0! | K34: =ROUNDUP(POWER(G34*$P$5/$Q$5,2),0) -> #DIV/0! | L34: =B34 & " ± " & (ROUNDUP(I34, 3)) -> ± 0
A35: =A34+1 -> 33 | D35: =POWER(C35/($O$5-1),0.5) -> 0 | E35: =B35+3*D35 -> 0 | F35: =B35-3*D35 -> 0 | G35: =D35/B35*100 -> #DIV/0! | H35: =D35/POWER($O$5, 0.5) -> 0 | I35: =H35*$P$5 -> 0 | J35: =I35/B35*100 -> #DIV/0! | K35: =ROUNDUP(POWER(G35*$P$5/$Q$5,2),0) -> #DIV/0! | L35: =B35 & " ± " & (ROUNDUP(I35, 3)) -> ± 0
A36: =A35+1 -> 34 | D36: =POWER(C36/($O$5-1),0.5) -> 0 | E36: =B36+3*D36 -> 0 | F36: =B36-3*D36 -> 0 | G36: =D36/B36*100 -> #DIV/0! | H36: =D36/POWER($O$5, 0.5) -> 0 | I36: =H36*$P$5 -> 0 | J36: =I36/B36*100 -> #DIV/0! | K36: =ROUNDUP(POWER(G36*$P$5/$Q$5,2),0) -> #DIV/0! | L36: =B36 & " ± " & (ROUNDUP(I36, 3)) -> ± 0
A37: =A36+1 -> 35 | D37: =POWER(C37/($O$5-1),0.5) -> 0 | E37: =B37+3*D37 -> 0 | F37: =B37-3*D37 -> 0 | G37: =D37/B37*100 -> #DIV/0! | H37: =D37/POWER($O$5, 0.5) -> 0 | I37: =H37*$P$5 -> 0 | J37: =I37/B37*100 -> #DIV/0! | K37: =ROUNDUP(POWER(G37*$P$5/$Q$5,2),0) -> #DIV/0! | L37: =B37 & " ± " & (ROUNDUP(I37, 3)) -> ± 0
A38: =A37+1 -> 36 | B38: 3382 | C38: 61080 | D38: =POWER(C38/($O$5-1),0.5) -> 45.89343 | E38: =B38+3*D38 -> 3519.6803 | F38: =B38-3*D38 -> 3244.3197 | G38: =D38/B38*100 -> 1.3569908 | H38: =D38/POWER($O$5, 0.5) -> 8.3789556 | I38: =H38*$P$5 -> 16.757911 | J38: =I38/B38*100 -> 0.49550299 | K38: =ROUNDUP(POWER(G38*$P$5/$Q$5,2),0) -> 1 | L38: =B38 & " ± " & (ROUNDUP(I38, 3)) -> 3382 ± 16,758
A39: =A38+1 -> 37 | D39: =POWER(C39/($O$5-1),0.5) -> 0 | E39: =B39+3*D39 -> 0 | F39: =B39-3*D39 -> 0 | G39: =D39/B39*100 -> #DIV/0! | H39: =D39/POWER($O$5, 0.5) -> 0 | I39: =H39*$P$5 -> 0 | J39: =I39/B39*100 -> #DIV/0! | K39: =ROUNDUP(POWER(G39*$P$5/$Q$5,2),0) -> #DIV/0! | L39: =B39 & " ± " & (ROUNDUP(I39, 3)) -> ± 0
A40: =A39+1 -> 38 | D40: =POWER(C40/($O$5-1),0.5) -> 0 | E40: =B40+3*D40 -> 0 | F40: =B40-3*D40 -> 0 | G40: =D40/B40*100 -> #DIV/0! | H40: =D40/POWER($O$5, 0.5) -> 0 | I40: =H40*$P$5 -> 0 | J40: =I40/B40*100 -> #DIV/0! | K40: =ROUNDUP(POWER(G40*$P$5/$Q$5,2),0) -> #DIV/0! | L40: =B40 & " ± " & (ROUNDUP(I40, 3)) -> ± 0
A41: =A40+1 -> 39 | D41: =POWER(C41/($O$5-1),0.5) -> 0 | E41: =B41+3*D41 -> 0 | F41: =B41-3*D41 -> 0 | G41: =D41/B41*100 -> #DIV/0! | H41: =D41/POWER($O$5, 0.5) -> 0 | I41: =H41*$P$5 -> 0 | J41: =I41/B41*100 -> #DIV/0! | K41: =ROUNDUP(POWER(G41*$P$5/$Q$5,2),0) -> #DIV/0! | L41: =B41 & " ± " & (ROUNDUP(I41, 3)) -> ± 0
...

Sheet Tв_23
A1: Серия экспериментов\статистика | B1: y_ср [м.е.] | C1: Σ((Δyi)^2) [м.е.^2] | D1: σ [м.е.] | E1: y_ср+3*σ [м.е.] | F1: y_ср-3*σ [м.е.] | G1: kв [%] | H1: σ0 [м.е.] | I1: Δy [м.е.] | J1: δy [%] | K1: N_мин | L1: y_ист [м.е.]
A3: 1 | B3: 2 | C3: 3480 | D3: =POWER(C3/($O$5-1),0.5) -> 10.954451 | E3: =B3+3*D3 -> 34.863353 | F3: =B3-3*D3 -> -30.863353 | G3: =D3/B3*100 -> 547.72256 | H3: =D3/POWER($O$5, 0.5) -> 2 | I3: =H3*$P$5 -> 4 | J3: =I3/B3*100 -> 200 | K3: =ROUNDUP(POWER(G3*$P$5/$Q$5,2),0) -> 48000 | L3: =B3 & " ± " & (ROUNDUP(I3, 3)) -> 2 ± 4
A4: =A3+1 -> 2 | D4: =POWER(C4/($O$5-1),0.5) -> 0 | E4: =B4+3*D4 -> 0 | F4: =B4-3*D4 -> 0 | G4: =D4/B4*100 -> #DIV/0! | H4: =D4/POWER($O$5, 0.5) -> 0 | I4: =H4*$P$5 -> 0 | J4: =I4/B4*100 -> #DIV/0! | K4: =ROUNDUP(POWER(G4*$P$5/$Q$5,2),0) -> #DIV/0! | L4: =B4 & " ± " & (ROUNDUP(I4, 3)) -> ± 0 | N4: p | O4: N | P4: t_pN | Q4: Δ [%]
A5: =A4+1 -> 3 | D5: =POWER(C5/($O$5-1),0.5) -> 0 | E5: =B5+3*D5 -> 0 | F5: =B5-3*D5 -> 0 | G5: =D5/B5*100 -> #DIV/0! | H5: =D5/POWER($O$5, 0.5) -> 0 | I5: =H5*$P$5 -> 0 | J5: =I5/B5*100 -> #DIV/0! | K5: =ROUNDUP(POWER(G5*$P$5/$Q$5,2),0) -> #DIV/0! | L5: =B5 & " ± " & (ROUNDUP(I5, 3)) -> ± 0 | N5: 0.95 | O5: 30 | P5: 2 | Q5: 5
A6: =A5+1 -> 4 | D6: =POWER(C6/($O$5-1),0.5) -> 0 | E6: =B6+3*D6 -> 0 | F6: =B6-3*D6 -> 0 | G6: =D6/B6*100 -> #DIV/0! | H6: =D6/POWER($O$5, 0.5) -> 0 | I6: =H6*$P$5 -> 0 | J6: =I6/B6*100 -> #DIV/0! | K6: =ROUNDUP(POWER(G6*$P$5/$Q$5,2),0) -> #DIV/0! | L6: =B6 & " ± " & (ROUNDUP(I6, 3)) -> ± 0
A7: =A6+1 -> 5 | D7: =POWER(C7/($O$5-1),0.5) -> 0 | E7: =B7+3*D7 -> 0 | F7: =B7-3*D7 -> 0 | G7: =D7/B7*100 -> #DIV/0! | H7: =D7/POWER($O$5, 0.5) -> 0 | I7: =H7*$P$5 -> 0 | J7: =I7/B7*100 -> #DIV/0! | K7: =ROUNDUP(POWER(G7*$P$5/$Q$5,2),0) -> #DIV/0! | L7: =B7 & " ± " & (ROUNDUP(I7, 3)) -> ± 0
A8: =A7+1 -> 6 | B8: 10 | C8: 29400 | D8: =POWER(C8/($O$5-1),0.5) -> 31.840118 | E8: =B8+3*D8 -> 105.52035 | F8: =B8-3*D8 -> -85.520353 | G8: =D8/B8*100 -> 318.40118 | H8: =D8/POWER($O$5, 0.5) -> 5.8131836 | I8: =H8*$P$5 -> 11.626367 | J8: =I8/B8*100 -> 116.26367 | K8: =ROUNDUP(POWER(G8*$P$5/$Q$5,2),0) -> 16221 | L8: =B8 & " ± " & (ROUNDUP(I8, 3)) -> 10 ± 11,627
A9: =A8+1 -> 7 | D9: =POWER(C9/($O$5-1),0.5) -> 0 | E9: =B9+3*D9 -> 0 | F9: =B9-3*D9 -> 0 | G9: =D9/B9*100 -> #DIV/0! | H9: =D9/POWER($O$5, 0.5) -> 0 | I9: =H9*$P$5 -> 0 | J9: =I9/B9*100 -> #DIV/0! | K9: =ROUNDUP(POWER(G9*$P$5/$Q$5,2),0) -> #DIV/0! | L9: =B9 & " ± " & (ROUNDUP(I9, 3)) -> ± 0
A10: =A9+1 -> 8 | D10: =POWER(C10/($O$5-1),0.5) -> 0 | E10: =B10+3*D10 -> 0 | F10: =B10-3*D10 -> 0 | G10: =D10/B10*100 -> #DIV/0! | H10: =D10/POWER($O$5, 0.5) -> 0 | I10: =H10*$P$5 -> 0 | J10: =I10/B10*100 -> #DIV/0! | K10: =ROUNDUP(POWER(G10*$P$5/$Q$5,2),0) -> #DIV/0! | L10: =B10 & " ± " & (ROUNDUP(I10, 3)) -> ± 0
A11: =A10+1 -> 9 | D11: =POWER(C11/($O$5-1),0.5) -> 0 | E11: =B11+3*D11 -> 0 | F11: =B11-3*D11 -> 0 | G11: =D11/B11*100 -> #DIV/0! | H11: =D11/POWER($O$5, 0.5) -> 0 | I11: =H11*$P$5 -> 0 | J11: =I11/B11*100 -> #DIV/0! | K11: =ROUNDUP(POWER(G11*$P$5/$Q$5,2),0) -> #DIV/0! | L11: =B11 & " ± " & (ROUNDUP(I11, 3)) -> ± 0
A12: =A11+1 -> 10 | D12: =POWER(C12/($O$5-1),0.5) -> 0 | E12: =B12+3*D12 -> 0 | F12: =B12-3*D12 -> 0 | G12: =D12/B12*100 -> #DIV/0! | H12: =D12/POWER($O$5, 0.5) -> 0 | I12: =H12*$P$5 -> 0 | J12: =I12/B12*100 -> #DIV/0! | K12: =ROUNDUP(POWER(G12*$P$5/$Q$5,2),0) -> #DIV/0! | L12: =B12 & " ± " & (ROUNDUP(I12, 3)) -> ± 0
A13: =A12+1 -> 11 | B13: 4 | C13: 13920 | D13: =POWER(C13/($O$5-1),0.5) -> 21.908902 | E13: =B13+3*D13 -> 69.726707 | F13: =B13-3*D13 -> -61.726707 | G13: =D13/B13*100 -> 547.72256 | H13: =D13/POWER($O$5, 0.5) -> 4 | I13: =H13*$P$5 -> 8 | J13: =I13/B13*100 -> 200 | K13: =ROUNDUP(POWER(G13*$P$5/$Q$5,2),0) -> 48000 | L13: =B13 & " ± " & (ROUNDUP(I13, 3)) -> 4 ± 8
A14: =A13+1 -> 12 | D14: =POWER(C14/($O$5-1),0.5) -> 0 | E14: =B14+3*D14 -> 0 | F14: =B14-3*D14 -> 0 | G14: =D14/B14*100 -> #DIV/0! | H14: =D14/POWER($O$5, 0.5) -> 0 | I14: =H14*$P$5 -> 0 | J14: =I14/B14*100 -> #DIV/0! | K14: =ROUNDUP(POWER(G14*$P$5/$Q$5,2),0) -> #DIV/0! | L14: =B14 & " ± " & (ROUNDUP(I14, 3)) -> ± 0
A15: =A14+1 -> 13 | D15: =POWER(C15/($O$5-1),0.5) -> 0 | E15: =B15+3*D15 -> 0 | F15: =B15-3*D15 -> 0 | G15: =D15/B15*100 -> #DIV/0! | H15: =D15/POWER($O$5, 0.5) -> 0 | I15: =H15*$P$5 -> 0 | J15: =I15/B15*100 -> #DIV/0! | K15: =ROUNDUP(POWER(G15*$P$5/$Q$5,2),0) -> #DIV/0! | L15: =B15 & " ± " & (ROUNDUP(I15, 3)) -> ± 0
A16: =A15+1 -> 14 | D16: =POWER(C16/($O$5-1),0.5) -> 0 | E16: =B16+3*D16 -> 0 | F16: =B16-3*D16 -> 0 | G16: =D16/B16*100 -> #DIV/0! | H16: =D16/POWER($O$5, 0.5) -> 0 | I16: =H16*$P$5 -> 0 | J16: =I16/B16*100 -> #DIV/0! | K16: =ROUNDUP(POWER(G16*$P$5/$Q$5,2),0) -> #DIV/0! | L16: =B16 & " ± " & (ROUNDUP(I16, 3)) -> ± 0
A17: =A16+1 -> 15 | D17: =POWER(C17/($O$5-1),0.5) -> 0 | E17: =B17+3*D17 -> 0 | F17: =B17-3*D17 -> 0 | G17: =D17/B17*100 -> #DIV/0! | H17: =D17/POWER($O$5, 0.5) -> 0 | I17: =H17*$P$5 -> 0 | J17: =I17/B17*100 -> #DIV/0! | K17: =ROUNDUP(POWER(G17*$P$5/$Q$5,2),0) -> #DIV/0! | L17: =B17 & " ± " & (ROUNDUP(I17, 3)) -> ± 0
A18: =A17+1 -> 16 | B18: 108 | C18: 146880 | D18: =POWER(C18/($O$5-1),0.5) -> 71.167602 | E18: =B18+3*D18 -> 321.50281 | F18: =B18-3*D18 -> -105.50281 | G18: =D18/B18*100 -> 65.895928 | H18: =D18/POWER($O$5, 0.5) -> 12.993367 | I18: =H18*$P$5 -> 25.986734 | J18: =I18/B18*100 -> 24.061791 | K18: =ROUNDUP(POWER(G18*$P$5/$Q$5,2),0) -> 695 | L18: =B18 & " ± " & (ROUNDUP(I18, 3)) -> 108 ± 25,987
A19: =A18+1 -> 17 | D19: =POWER(C19/($O$5-1),0.5) -> 0 | E19: =B19+3*D19 -> 0 | F19: =B19-3*D19 -> 0 | G19: =D19/B19*100 -> #DIV/0! | H19: =D19/POWER($O$5, 0.5) -> 0 | I19: =H19*$P$5 -> 0 | J19: =I19/B19*100 -> #DIV/0! | K19: =ROUNDUP(POWER(G19*$P$5/$Q$5,2),0) -> #DIV/0! | L19: =B19 & " ± " & (ROUNDUP(I19, 3)) -> ± 0
A20: =A19+1 -> 18 | D20: =POWER(C20/($O$5-1),0.5) -> 0 | E20: =B20+3*D20 -> 0 | F20: =B20-3*D20 -> 0 | G20: =D20/B20*100 -> #DIV/0! | H20: =D20/POWER($O$5, 0.5) -> 0 | I20: =H20*$P$5 -> 0 | J20: =I20/B20*100 -> #DIV/0! | K20: =ROUNDUP(POWER(G20*$P$5/$Q$5,2),0) -> #DIV/0! | L20: =B20 & " ± " & (ROUNDUP(I20, 3)) -> ± 0
A21: =A20+1 -> 19 | D21: =POWER(C21/($O$5-1),0.5) -> 0 | E21: =B21+3*D21 -> 0 | F21: =B21-3*D21 -> 0 | G21: =D21/B21*100 -> #DIV/0! | H21: =D21/POWER($O$5, 0.5) -> 0 | I21: =H21*$P$5 -> 0 | J21: =I21/B21*100 -> #DIV/0! | K21: =ROUNDUP(POWER(G21*$P$5/$Q$5,2),0) -> #DIV/0! | L21: =B21 & " ± " & (ROUNDUP(I21, 3)) -> ± 0
A22: =A21+1 -> 20 | D22: =POWER(C22/($O$5-1),0.5) -> 0 | E22: =B22+3*D22 -> 0 | F22: =B22-3*D22 -> 0 | G22: =D22/B22*100 -> #DIV/0! | H22: =D22/POWER($O$5, 0.5) -> 0 | I22: =H22*$P$5 -> 0 | J22: =I22/B22*100 -> #DIV/0! | K22: =ROUNDUP(POWER(G22*$P$5/$Q$5,2),0) -> #DIV/0! | L22: =B22 & " ± " & (ROUNDUP(I22, 3)) -> ± 0
A23: =A22+1 -> 21 | B23: 34 | C23: 62520 | D23: =POWER(C23/($O$5-1),0.5) -> 46.431262 | E23: =B23+3*D23 -> 173.29379 | F23: =B23-3*D23 -> -105.29379 | G23: =D23/B23*100 -> 136.56253 | H23: =D23/POWER($O$5, 0.5) -> 8.4771498 | I23: =H23*$P$5 -> 16.9543 | J23: =I23/B23*100 -> 49.865587 | K23: =ROUNDUP(POWER(G23*$P$5/$Q$5,2),0) -> 2984 | L23: =B23 & " ± " & (ROUNDUP(I23, 3)) -> 34 ± 16,955
A24: =A23+1 -> 22 | D24: =POWER(C24/($O$5-1),0.5) -> 0 | E24: =B24+3*D24 -> 0 | F24: =B24-3*D24 -> 0 | G24: =D24/B24*100 -> #DIV/0! | H24: =D24/POWER($O$5, 0.5) -> 0 | I24: =H24*$P$5 -> 0 | J24: =I24/B24*100 -> #DIV/0! | K24: =ROUNDUP(POWER(G24*$P$5/$Q$5,2),0) -> #DIV/0! | L24: =B24 & " ± " & (ROUNDUP(I24, 3)) -> ± 0
A25: =A24+1 -> 23 | D25: =POWER(C25/($O$5-1),0.5) -> 0 | E25: =B25+3*D25 -> 0 | F25: =B25-3*D25 -> 0 | G25: =D25/B25*100 -> #DIV/0! | H25: =D25/POWER($O$5, 0.5) -> 0 | I25: =H25*$P$5 -> 0 | J25: =I25/B25*100 -> #DIV/0! | K25: =ROUNDUP(POWER(G25*$P$5/$Q$5,2),0) -> #DIV/0! | L25: =B25 & " ± " & (ROUNDUP(I25, 3)) -> ± 0
A26: =A25+1 -> 24 | D26: =POWER(C26/($O$5-1),0.5) -> 0 | E26: =B26+3*D26 -> 0 | F26: =B26-3*D26 -> 0 | G26: =D26/B26*100 -> #DIV/0! | H26: =D26/POWER($O$5, 0.5) -> 0 | I26: =H26*$P$5 -> 0 | J26: =I26/B26*100 -> #DIV/0! | K26: =ROUNDUP(POWER(G26*$P$5/$Q$5,2),0) -> #DIV/0! | L26: =B26 & " ± " & (ROUNDUP(I26, 3)) -> ± 0
A27: =A26+1 -> 25 | D27: =POWER(C27/($O$5-1),0.5) -> 0 | E27: =B27+3*D27 -> 0 | F27: =B27-3*D27 -> 0 | G27: =D27/B27*100 -> #DIV/0! | H27: =D27/POWER($O$5, 0.5) -> 0 | I27: =H27*$P$5 -> 0 | J27: =I27/B27*100 -> #DIV/0! | K27: =ROUNDUP(POWER(G27*$P$5/$Q$5,2),0) -> #DIV/0! | L27: =B27 & " ± " & (ROUNDUP(I27, 3)) -> ± 0
A28: =A27+1 -> 26 | B28: 438 | C28: 1433880 | D28: =POWER(C28/($O$5-1),0.5) -> 222.36038 | E28: =B28+3*D28 -> 1105.0811 | F28: =B28-3*D28 -> -229.08114 | G28: =D28/B28*100 -> 50.76721 | H28: =D28/POWER($O$5, 0.5) -> 40.597265 | I28: =H28*$P$5 -> 81.19453 | J28: =I28/B28*100 -> 18.537564 | K28: =ROUNDUP(POWER(G28*$P$5/$Q$5,2),0) -> 413 | L28: =B28 & " ± " & (ROUNDUP(I28, 3)) -> 438 ± 81,195
A29: =A28+1 -> 27 | D29: =POWER(C29/($O$5-1),0.5) -> 0 | E29: =B29+3*D29 -> 0 | F29: =B29-3*D29 -> 0 | G29: =D29/B29*100 -> #DIV/0! | H29: =D29/POWER($O$5, 0.5) -> 0 | I29: =H29*$P$5 -> 0 | J29: =I29/B29*100 -> #DIV/0! | K29: =ROUNDUP(POWER(G29*$P$5/$Q$5,2),0) -> #DIV/0! | L29: =B29 & " ± " & (ROUNDUP(I29, 3)) -> ± 0
A30: =A29+1 -> 28 | D30: =POWER(C30/($O$5-1),0.5) -> 0 | E30: =B30+3*D30 -> 0 | F30: =B30-3*D30 -> 0 | G30: =D30/B30*100 -> #DIV/0! | H30: =D30/POWER($O$5, 0.5) -> 0 | I30: =H30*$P$5 -> 0 | J30: =I30/B30*100 -> #DIV/0! | K30: =ROUNDUP(POWER(G30*$P$5/$Q$5,2),0) -> #DIV/0! | L30: =B30 & " ± " & (ROUNDUP(I30, 3)) -> ± 0
A31: =A30+1 -> 29 | D31: =POWER(C31/($O$5-1),0.5) -> 0 | E31: =B31+3*D31 -> 0 | F31: =B31-3*D31 -> 0 | G31: =D31/B31*100 -> #DIV/0! | H31: =D31/POWER($O$5, 0.5) -> 0 | I31: =H31*$P$5 -> 0 | J31: =I31/B31*100 -> #DIV/0! | K31: =ROUNDUP(POWER(G31*$P$5/$Q$5,2),0) -> #DIV/0! | L31: =B31 & " ± " & (ROUNDUP(I31, 3)) -> ± 0
A32: =A31+1 -> 30 | D32: =POWER(C32/($O$5-1),0.5) -> 0 | E32: =B32+3*D32 -> 0 | F32: =B32-3*D32 -> 0 | G32: =D32/B32*100 -> #DIV/0! | H32: =D32/POWER($O$5, 0.5) -> 0 | I32: =H32*$P$5 -> 0 | J32: =I32/B32*100 -> #DIV/0! | K32: =ROUNDUP(POWER(G32*$P$5/$Q$5,2),0) -> #DIV/0! | L32: =B32 & " ± " & (ROUNDUP(I32, 3)) -> ± 0
A33: =A32+1 -> 31 | B33: 64 | C33: 78720 | D33: =POWER(C33/($O$5-1),0.5) -> 52.100698 | E33: =B33+3*D33 -> 220.30209 | F33: =B33-3*D33 -> -92.302095 | G33: =D33/B33*100 -> 81.407341 | H33: =D33/POWER($O$5, 0.5) -> 9.5122426 | I33: =H33*$P$5 -> 19.024485 | J33: =I33/B33*100 -> 29.725758 | K33: =ROUNDUP(POWER(G33*$P$5/$Q$5,2),0) -> 1061 | L33: =B33 & " ± " & (ROUNDUP(I33, 3)) -> 64 ± 19,025
A34: =A33+1 -> 32 | D34: =POWER(C34/($O$5-1),0.5) -> 0 | E34: =B34+3*D34 -> 0 | F34: =B34-3*D34 -> 0 | G34: =D34/B34*100 -> #DIV/0! | H34: =D34/POWER($O$5, 0.5) -> 0 | I34: =H34*$P$5 -> 0 | J34: =I34/B34*100 -> #DIV/0! | K34: =ROUNDUP(POWER(G34*$P$5/$Q$5,2),0) -> #DIV/0! | L34: =B34 & " ± " & (ROUNDUP(I34, 3)) -> ± 0
A35: =A34+1 -> 33 | D35: =POWER(C35/($O$5-1),0.5) -> 0 | E35: =B35+3*D35 -> 0 | F35: =B35-3*D35 -> 0 | G35: =D35/B35*100 -> #DIV/0! | H35: =D35/POWER($O$5, 0.5) -> 0 | I35: =H35*$P$5 -> 0 | J35: =I35/B35*100 -> #DIV/0! | K35: =ROUNDUP(POWER(G35*$P$5/$Q$5,2),0) -> #DIV/0! | L35: =B35 & " ± " & (ROUNDUP(I35, 3)) -> ± 0
A36: =A35+1 -> 34 | D36: =POWER(C36/($O$5-1),0.5) -> 0 | E36: =B36+3*D36 -> 0 | F36: =B36-3*D36 -> 0 | G36: =D36/B36*100 -> #DIV/0! | H36: =D36/POWER($O$5, 0.5) -> 0 | I36: =H36*$P$5 -> 0 | J36: =I36/B36*100 -> #DIV/0! | K36: =ROUNDUP(POWER(G36*$P$5/$Q$5,2),0) -> #DIV/0! | L36: =B36 & " ± " & (ROUNDUP(I36, 3)) -> ± 0
A37: =A36+1 -> 35 | D37: =POWER(C37/($O$5-1),0.5) -> 0 | E37: =B37+3*D37 -> 0 | F37: =B37-3*D37 -> 0 | G37: =D37/B37*100 -> #DIV/0! | H37: =D37/POWER($O$5, 0.5) -> 0 | I37: =H37*$P$5 -> 0 | J37: =I37/B37*100 -> #DIV/0! | K37: =ROUNDUP(POWER(G37*$P$5/$Q$5,2),0) -> #DIV/0! | L37: =B37 & " ± " & (ROUNDUP(I37, 3)) -> ± 0
A38: =A37+1 -> 36 | B38: 74 | C38: 69720 | D38: =POWER(C38/($O$5-1),0.5) -> 49.032009 | E38: =B38+3*D38 -> 221.09603 | F38: =B38-3*D38 -> -73.096028 | G38: =D38/B38*100 -> 66.259472 | H38: =D38/POWER($O$5, 0.5) -> 8.9519792 | I38: =H38*$P$5 -> 17.903958 | J38: =I38/B38*100 -> 24.194538 | K38: =ROUNDUP(POWER(G38*$P$5/$Q$5,2),0) -> 703 | L38: =B38 & " ± " & (ROUNDUP(I38, 3)) -> 74 ± 17,904
A39: =A38+1 -> 37 | D39: =POWER(C39/($O$5-1),0.5) -> 0 | E39: =B39+3*D39 -> 0 | F39: =B39-3*D39 -> 0 | G39: =D39/B39*100 -> #DIV/0! | H39: =D39/POWER($O$5, 0.5) -> 0 | I39: =H39*$P$5 -> 0 | J39: =I39/B39*100 -> #DIV/0! | K39: =ROUNDUP(POWER(G39*$P$5/$Q$5,2),0) -> #DIV/0! | L39: =B39 & " ± " & (ROUNDUP(I39, 3)) -> ± 0
A40: =A39+1 -> 38 | D40: =POWER(C40/($O$5-1),0.5) -> 0 | E40: =B40+3*D40 -> 0 | F40: =B40-3*D40 -> 0 | G40: =D40/B40*100 -> #DIV/0! | H40: =D40/POWER($O$5, 0.5) -> 0 | I40: =H40*$P$5 -> 0 | J40: =I40/B40*100 -> #DIV/0! | K40: =ROUNDUP(POWER(G40*$P$5/$Q$5,2),0) -> #DIV/0! | L40: =B40 & " ± " & (ROUNDUP(I40, 3)) -> ± 0
A41: =A40+1 -> 39 | D41: =POWER(C41/($O$5-1),0.5) -> 0 | E41: =B41+3*D41 -> 0 | F41: =B41-3*D41 -> 0 | G41: =D41/B41*100 -> #DIV/0! | H41: =D41/POWER($O$5, 0.5) -> 0 | I41: =H41*$P$5 -> 0 | J41: =I41/B41*100 -> #DIV/0! | K41: =ROUNDUP(POWER(G41*$P$5/$Q$5,2),0) -> #DIV/0! | L41: =B41 & " ± " & (ROUNDUP(I41, 3)) -> ± 0
...

Sheet Tв_3
A1: Серия экспериментов\статистика | B1: y_ср [м.е.] | C1: Σ((Δyi)^2) [м.е.^2] | D1: σ [м.е.] | E1: y_ср+3*σ [м.е.] | F1: y_ср-3*σ [м.е.] | G1: kв [%] | H1: σ0 [м.е.] | I1: Δy [м.е.] | J1: δy [%] | K1: N_мин | L1: y_ист [м.е.]
A3: 1 | B3: 2 | C3: 3480 | D3: =POWER(C3/($O$5-1),0.5) -> 10.954451 | E3: =B3+3*D3 -> 34.863353 | F3: =B3-3*D3 -> -30.863353 | G3: =D3/B3*100 -> 547.72256 | H3: =D3/POWER($O$5, 0.5) -> 2 | I3: =H3*$P$5 -> 4 | J3: =I3/B3*100 -> 200 | K3: =ROUNDUP(POWER(G3*$P$5/$Q$5,2),0) -> 48000 | L3: =B3 & " ± " & (ROUNDUP(I3, 3)) -> 2 ± 4
A4: =A3+1 -> 2 | D4: =POWER(C4/($O$5-1),0.5) -> 0 | E4: =B4+3*D4 -> 0 | F4: =B4-3*D4 -> 0 | G4: =D4/B4*100 -> #DIV/0! | H4: =D4/POWER($O$5, 0.5) -> 0 | I4: =H4*$P$5 -> 0 | J4: =I4/B4*100 -> #DIV/0! | K4: =ROUNDUP(POWER(G4*$P$5/$Q$5,2),0) -> #DIV/0! | L4: =B4 & " ± " & (ROUNDUP(I4, 3)) -> ± 0 | N4: p | O4: N | P4: t_pN | Q4: Δ [%]
A5: =A4+1 -> 3 | D5: =POWER(C5/($O$5-1),0.5) -> 0 | E5: =B5+3*D5 -> 0 | F5: =B5-3*D5 -> 0 | G5: =D5/B5*100 -> #DIV/0! | H5: =D5/POWER($O$5, 0.5) -> 0 | I5: =H5*$P$5 -> 0 | J5: =I5/B5*100 -> #DIV/0! | K5: =ROUNDUP(POWER(G5*$P$5/$Q$5,2),0) -> #DIV/0! | L5: =B5 & " ± " & (ROUNDUP(I5, 3)) -> ± 0 | N5: 0.95 | O5: 30 | P5: 2 | Q5: 5
A6: =A5+1 -> 4 | D6: =POWER(C6/($O$5-1),0.5) -> 0 | E6: =B6+3*D6 -> 0 | F6: =B6-3*D6 -> 0 | G6: =D6/B6*100 -> #DIV/0! | H6: =D6/POWER($O$5, 0.5) -> 0 | I6: =H6*$P$5 -> 0 | J6: =I6/B6*100 -> #DIV/0! | K6: =ROUNDUP(POWER(G6*$P$5/$Q$5,2),0) -> #DIV/0! | L6: =B6 & " ± " & (ROUNDUP(I6, 3)) -> ± 0
A7: =A6+1 -> 5 | D7: =POWER(C7/($O$5-1),0.5) -> 0 | E7: =B7+3*D7 -> 0 | F7: =B7-3*D7 -> 0 | G7: =D7/B7*100 -> #DIV/0! | H7: =D7/POWER($O$5, 0.5) -> 0 | I7: =H7*$P$5 -> 0 | J7: =I7/B7*100 -> #DIV/0! | K7: =ROUNDUP(POWER(G7*$P$5/$Q$5,2),0) -> #DIV/0! | L7: =B7 & " ± " & (ROUNDUP(I7, 3)) -> ± 0
A8: =A7+1 -> 6 | B8: 8 | C8: 26880 | D8: =POWER(C8/($O$5-1),0.5) -> 30.444976 | E8: =B8+3*D8 -> 99.334927 | F8: =B8-3*D8 -> -83.334927 | G8: =D8/B8*100 -> 380.5622 | H8: =D8/POWER($O$5, 0.5) -> 5.5584667 | I8: =H8*$P$5 -> 11.116933 | J8: =I8/B8*100 -> 138.96167 | K8: =ROUNDUP(POWER(G8*$P$5/$Q$5,2),0) -> 23173 | L8: =B8 & " ± " & (ROUNDUP(I8, 3)) -> 8 ± 11,117
A9: =A8+1 -> 7 | D9: =POWER(C9/($O$5-1),0.5) -> 0 | E9: =B9+3*D9 -> 0 | F9: =B9-3*D9 -> 0 | G9: =D9/B9*100 -> #DIV/0! | H9: =D9/POWER($O$5, 0.5) -> 0 | I9: =H9*$P$5 -> 0 | J9: =I9/B9*100 -> #DIV/0! | K9: =ROUNDUP(POWER(G9*$P$5/$Q$5,2),0) -> #DIV/0! | L9: =B9 & " ± " & (ROUNDUP(I9, 3)) -> ± 0
A10: =A9+1 -> 8 | D10: =POWER(C10/($O$5-1),0.5) -> 0 | E10: =B10+3*D10 -> 0 | F10: =B10-3*D10 -> 0 | G10: =D10/B10*100 -> #DIV/0! | H10: =D10/POWER($O$5, 0.5) -> 0 | I10: =H10*$P$5 -> 0 | J10: =I10/B10*100 -> #DIV/0! | K10: =ROUNDUP(POWER(G10*$P$5/$Q$5,2),0) -> #DIV/0! | L10: =B10 & " ± " & (ROUNDUP(I10, 3)) -> ± 0
A11: =A10+1 -> 9 | D11: =POWER(C11/($O$5-1),0.5) -> 0 | E11: =B11+3*D11 -> 0 | F11: =B11-3*D11 -> 0 | G11: =D11/B11*100 -> #DIV/0! | H11: =D11/POWER($O$5, 0.5) -> 0 | I11: =H11*$P$5 -> 0 | J11: =I11/B11*100 -> #DIV/0! | K11: =ROUNDUP(POWER(G11*$P$5/$Q$5,2),0) -> #DIV/0! | L11: =B11 & " ± " & (ROUNDUP(I11, 3)) -> ± 0
A12: =A11+1 -> 10 | D12: =POWER(C12/($O$5-1),0.5) -> 0 | E12: =B12+3*D12 -> 0 | F12: =B12-3*D12 -> 0 | G12: =D12/B12*100 -> #DIV/0! | H12: =D12/POWER($O$5, 0.5) -> 0 | I12: =H12*$P$5 -> 0 | J12: =I12/B12*100 -> #DIV/0! | K12: =ROUNDUP(POWER(G12*$P$5/$Q$5,2),0) -> #DIV/0! | L12: =B12 & " ± " & (ROUNDUP(I12, 3)) -> ± 0
A13: =A12+1 -> 11 | B13: 4 | C13: 13920 | D13: =POWER(C13/($O$5-1),0.5) -> 21.908902 | E13: =B13+3*D13 -> 69.726707 | F13: =B13-3*D13 -> -61.726707 | G13: =D13/B13*100 -> 547.72256 | H13: =D13/POWER($O$5, 0.5) -> 4 | I13: =H13*$P$5 -> 8 | J13: =I13/B13*100 -> 200 | K13: =ROUNDUP(POWER(G13*$P$5/$Q$5,2),0) -> 48000 | L13: =B13 & " ± " & (ROUNDUP(I13, 3)) -> 4 ± 8
A14: =A13+1 -> 12 | D14: =POWER(C14/($O$5-1),0.5) -> 0 | E14: =B14+3*D14 -> 0 | F14: =B14-3*D14 -> 0 | G14: =D14/B14*100 -> #DIV/0! | H14: =D14/POWER($O$5, 0.5) -> 0 | I14: =H14*$P$5 -> 0 | J14: =I14/B14*100 -> #DIV/0! | K14: =ROUNDUP(POWER(G14*$P$5/$Q$5,2),0) -> #DIV/0! | L14: =B14 & " ± " & (ROUNDUP(I14, 3)) -> ± 0
A15: =A14+1 -> 13 | D15: =POWER(C15/($O$5-1),0.5) -> 0 | E15: =B15+3*D15 -> 0 | F15: =B15-3*D15 -> 0 | G15: =D15/B15*100 -> #DIV/0! | H15: =D15/POWER($O$5, 0.5) -> 0 | I15: =H15*$P$5 -> 0 | J15: =I15/B15*100 -> #DIV/0! | K15: =ROUNDUP(POWER(G15*$P$5/$Q$5,2),0) -> #DIV/0! | L15: =B15 & " ± " & (ROUNDUP(I15, 3)) -> ± 0
A16: =A15+1 -> 14 | D16: =POWER(C16/($O$5-1),0.5) -> 0 | E16: =B16+3*D16 -> 0 | F16: =B16-3*D16 -> 0 | G16: =D16/B16*100 -> #DIV/0! | H16: =D16/POWER($O$5, 0.5) -> 0 | I16: =H16*$P$5 -> 0 | J16: =I16/B16*100 -> #DIV/0! | K16: =ROUNDUP(POWER(G16*$P$5/$Q$5,2),0) -> #DIV/0! | L16: =B16 & " ± " & (ROUNDUP(I16, 3)) -> ± 0
A17: =A16+1 -> 15 | D17: =POWER(C17/($O$5-1),0.5) -> 0 | E17: =B17+3*D17 -> 0 | F17: =B17-3*D17 -> 0 | G17: =D17/B17*100 -> #DIV/0! | H17: =D17/POWER($O$5, 0.5) -> 0 | I17: =H17*$P$5 -> 0 | J17: =I17/B17*100 -> #DIV/0! | K17: =ROUNDUP(POWER(G17*$P$5/$Q$5,2),0) -> #DIV/0! | L17: =B17 & " ± " & (ROUNDUP(I17, 3)) -> ± 0
A18: =A17+1 -> 16 | B18: 40 | C18: 74400 | D18: =POWER(C18/($O$5-1),0.5) -> 50.650935 | E18: =B18+3*D18 -> 191.95281 | F18: =B18-3*D18 -> -111.95281 | G18: =D18/B18*100 -> 126.62734 | H18: =D18/POWER($O$5, 0.5) -> 9.2475533 | I18: =H18*$P$5 -> 18.495107 | J18: =I18/B18*100 -> 46.237766 | K18: =ROUNDUP(POWER(G18*$P$5/$Q$5,2),0) -> 2566 | L18: =B18 & " ± " & (ROUNDUP(I18, 3)) -> 40 ± 18,496
A19: =A18+1 -> 17 | D19: =POWER(C19/($O$5-1),0.5) -> 0 | E19: =B19+3*D19 -> 0 | F19: =B19-3*D19 -> 0 | G19: =D19/B19*100 -> #DIV/0! | H19: =D19/POWER($O$5, 0.5) -> 0 | I19: =H19*$P$5 -> 0 | J19: =I19/B19*100 -> #DIV/0! | K19: =ROUNDUP(POWER(G19*$P$5/$Q$5,2),0) -> #DIV/0! | L19: =B19 & " ± " & (ROUNDUP(I19, 3)) -> ± 0
A20: =A19+1 -> 18 | D20: =POWER(C20/($O$5-1),0.5) -> 0 | E20: =B20+3*D20 -> 0 | F20: =B20-3*D20 -> 0 | G20: =D20/B20*100 -> #DIV/0! | H20: =D20/POWER($O$5, 0.5) -> 0 | I20: =H20*$P$5 -> 0 | J20: =I20/B20*100 -> #DIV/0! | K20: =ROUNDUP(POWER(G20*$P$5/$Q$5,2),0) -> #DIV/0! | L20: =B20 & " ± " & (ROUNDUP(I20, 3)) -> ± 0
A21: =A20+1 -> 19 | D21: =POWER(C21/($O$5-1),0.5) -> 0 | E21: =B21+3*D21 -> 0 | F21: =B21-3*D21 -> 0 | G21: =D21/B21*100 -> #DIV/0! | H21: =D21/POWER($O$5, 0.5) -> 0 | I21: =H21*$P$5 -> 0 | J21: =I21/B21*100 -> #DIV/0! | K21: =ROUNDUP(POWER(G21*$P$5/$Q$5,2),0) -> #DIV/0! | L21: =B21 & " ± " & (ROUNDUP(I21, 3)) -> ± 0
A22: =A21+1 -> 20 | D22: =POWER(C22/($O$5-1),0.5) -> 0 | E22: =B22+3*D22 -> 0 | F22: =B22-3*D22 -> 0 | G22: =D22/B22*100 -> #DIV/0! | H22: =D22/POWER($O$5, 0.5) -> 0 | I22: =H22*$P$5 -> 0 | J22: =I22/B22*100 -> #DIV/0! | K22: =ROUNDUP(POWER(G22*$P$5/$Q$5,2),0) -> #DIV/0! | L22: =B22 & " ± " & (ROUNDUP(I22, 3)) -> ± 0
A23: =A22+1 -> 21 | B23: 14 | C23: 26520 | D23: =POWER(C23/($O$5-1),0.5) -> 30.240416 | E23: =B23+3*D23 -> 104.72125 | F23: =B23-3*D23 -> -76.721248 | G23: =D23/B23*100 -> 216.00297 | H23: =D23/POWER($O$5, 0.5) -> 5.5211193 | I23: =H23*$P$5 -> 11.042239 | J23: =I23/B23*100 -> 78.873133 | K23: =ROUNDUP(POWER(G23*$P$5/$Q$5,2),0) -> 7466 | L23: =B23 & " ± " & (ROUNDUP(I23, 3)) -> 14 ± 11,043
A24: =A23+1 -> 22 | D24: =POWER(C24/($O$5-1),0.5) -> 0 | E24: =B24+3*D24 -> 0 | F24: =B24-3*D24 -> 0 | G24: =D24/B24*100 -> #DIV/0! | H24: =D24/POWER($O$5, 0.5) -> 0 | I24: =H24*$P$5 -> 0 | J24: =I24/B24*100 -> #DIV/0! | K24: =ROUNDUP(POWER(G24*$P$5/$Q$5,2),0) -> #DIV/0! | L24: =B24 & " ± " & (ROUNDUP(I24, 3)) -> ± 0
A25: =A24+1 -> 23 | D25: =POWER(C25/($O$5-1),0.5) -> 0 | E25: =B25+3*D25 -> 0 | F25: =B25-3*D25 -> 0 | G25: =D25/B25*100 -> #DIV/0! | H25: =D25/POWER($O$5, 0.5) -> 0 | I25: =H25*$P$5 -> 0 | J25: =I25/B25*100 -> #DIV/0! | K25: =ROUNDUP(POWER(G25*$P$5/$Q$5,2),0) -> #DIV/0! | L25: =B25 & " ± " & (ROUNDUP(I25, 3)) -> ± 0
A26: =A25+1 -> 24 | D26: =POWER(C26/($O$5-1),0.5) -> 0 | E26: =B26+3*D26 -> 0 | F26: =B26-3*D26 -> 0 | G26: =D26/B26*100 -> #DIV/0! | H26: =D26/POWER($O$5, 0.5) -> 0 | I26: =H26*$P$5 -> 0 | J26: =I26/B26*100 -> #DIV/0! | K26: =ROUNDUP(POWER(G26*$P$5/$Q$5,2),0) -> #DIV/0! | L26: =B26 & " ± " & (ROUNDUP(I26, 3)) -> ± 0
A27: =A26+1 -> 25 | D27: =POWER(C27/($O$5-1),0.5) -> 0 | E27: =B27+3*D27 -> 0 | F27: =B27-3*D27 -> 0 | G27: =D27/B27*100 -> #DIV/0! | H27: =D27/POWER($O$5, 0.5) -> 0 | I27: =H27*$P$5 -> 0 | J27: =I27/B27*100 -> #DIV/0! | K27: =ROUNDUP(POWER(G27*$P$5/$Q$5,2),0) -> #DIV/0! | L27: =B27 & " ± " & (ROUNDUP(I27, 3)) -> ± 0
A28: =A27+1 -> 26 | B28: 206 | C28: 840120 | D28: =POWER(C28/($O$5-1),0.5) -> 170.20474 | E28: =B28+3*D28 -> 716.61423 | F28: =B28-3*D28 -> -304.61423 | G28: =D28/B28*100 -> 82.623663 | H28: =D28/POWER($O$5, 0.5) -> 31.074993 | I28: =H28*$P$5 -> 62.149985 | J28: =I28/B28*100 -> 30.169896 | K28: =ROUNDUP(POWER(G28*$P$5/$Q$5,2),0) -> 1093 | L28: =B28 & " ± " & (ROUNDUP(I28, 3)) -> 206 ± 62,15
A29: =A28+1 -> 27 | D29: =POWER(C29/($O$5-1),0.5) -> 0 | E29: =B29+3*D29 -> 0 | F29: =B29-3*D29 -> 0 | G29: =D29/B29*100 -> #DIV/0! | H29: =D29/POWER($O$5, 0.5) -> 0 | I29: =H29*$P$5 -> 0 | J29: =I29/B29*100 -> #DIV/0! | K29: =ROUNDUP(POWER(G29*$P$5/$Q$5,2),0) -> #DIV/0! | L29: =B29 & " ± " & (ROUNDUP(I29, 3)) -> ± 0
A30: =A29+1 -> 28 | D30: =POWER(C30/($O$5-1),0.5) -> 0 | E30: =B30+3*D30 -> 0 | F30: =B30-3*D30 -> 0 | G30: =D30/B30*100 -> #DIV/0! | H30: =D30/POWER($O$5, 0.5) -> 0 | I30: =H30*$P$5 -> 0 | J30: =I30/B30*100 -> #DIV/0! | K30: =ROUNDUP(POWER(G30*$P$5/$Q$5,2),0) -> #DIV/0! | L30: =B30 & " ± " & (ROUNDUP(I30, 3)) -> ± 0
A31: =A30+1 -> 29 | D31: =POWER(C31/($O$5-1),0.5) -> 0 | E31: =B31+3*D31 -> 0 | F31: =B31-3*D31 -> 0 | G31: =D31/B31*100 -> #DIV/0! | H31: =D31/POWER($O$5, 0.5) -> 0 | I31: =H31*$P$5 -> 0 | J31: =I31/B31*100 -> #DIV/0! | K31: =ROUNDUP(POWER(G31*$P$5/$Q$5,2),0) -> #DIV/0! | L31: =B31 & " ± " & (ROUNDUP(I31, 3)) -> ± 0
A32: =A31+1 -> 30 | D32: =POWER(C32/($O$5-1),0.5) -> 0 | E32: =B32+3*D32 -> 0 | F32: =B32-3*D32 -> 0 | G32: =D32/B32*100 -> #DIV/0! | H32: =D32/POWER($O$5, 0.5) -> 0 | I32: =H32*$P$5 -> 0 | J32: =I32/B32*100 -> #DIV/0! | K32: =ROUNDUP(POWER(G32*$P$5/$Q$5,2),0) -> #DIV/0! | L32: =B32 & " ± " & (ROUNDUP(I32, 3)) -> ± 0
A33: =A32+1 -> 31 | B33: 30 | C33: 63000 | D33: =POWER(C33/($O$5-1),0.5) -> 46.60916 | E33: =B33+3*D33 -> 169.82748 | F33: =B33-3*D33 -> -109.82748 | G33: =D33/B33*100 -> 155.36387 | H33: =D33/POWER($O$5, 0.5) -> 8.5096294 | I33: =H33*$P$5 -> 17.019259 | J33: =I33/B33*100 -> 56.730863 | K33: =ROUNDUP(POWER(G33*$P$5/$Q$5,2),0) -> 3863 | L33: =B33 & " ± " & (ROUNDUP(I33, 3)) -> 30 ± 17,02
A34: =A33+1 -> 32 | D34: =POWER(C34/($O$5-1),0.5) -> 0 | E34: =B34+3*D34 -> 0 | F34: =B34-3*D34 -> 0 | G34: =D34/B34*100 -> #DIV/0! | H34: =D34/POWER($O$5, 0.5) -> 0 | I34: =H34*$P$5 -> 0 | J34: =I34/B34*100 -> #DIV/0! | K34: =ROUNDUP(POWER(G34*$P$5/$Q$5,2),0) -> #DIV/0! | L34: =B34 & " ± " & (ROUNDUP(I34, 3)) -> ± 0
A35: =A34+1 -> 33 | D35: =POWER(C35/($O$5-1),0.5) -> 0 | E35: =B35+3*D35 -> 0 | F35: =B35-3*D35 -> 0 | G35: =D35/B35*100 -> #DIV/0! | H35: =D35/POWER($O$5, 0.5) -> 0 | I35: =H35*$P$5 -> 0 | J35: =I35/B35*100 -> #DIV/0! | K35: =ROUNDUP(POWER(G35*$P$5/$Q$5,2),0) -> #DIV/0! | L35: =B35 & " ± " & (ROUNDUP(I35, 3)) -> ± 0
A36: =A35+1 -> 34 | D36: =POWER(C36/($O$5-1),0.5) -> 0 | E36: =B36+3*D36 -> 0 | F36: =B36-3*D36 -> 0 | G36: =D36/B36*100 -> #DIV/0! | H36: =D36/POWER($O$5, 0.5) -> 0 | I36: =H36*$P$5 -> 0 | J36: =I36/B36*100 -> #DIV/0! | K36: =ROUNDUP(POWER(G36*$P$5/$Q$5,2),0) -> #DIV/0! | L36: =B36 & " ± " & (ROUNDUP(I36, 3)) -> ± 0
A37: =A36+1 -> 35 | D37: =POWER(C37/($O$5-1),0.5) -> 0 | E37: =B37+3*D37 -> 0 | F37: =B37-3*D37 -> 0 | G37: =D37/B37*100 -> #DIV/0! | H37: =D37/POWER($O$5, 0.5) -> 0 | I37: =H37*$P$5 -> 0 | J37: =I37/B37*100 -> #DIV/0! | K37: =ROUNDUP(POWER(G37*$P$5/$Q$5,2),0) -> #DIV/0! | L37: =B37 & " ± " & (ROUNDUP(I37, 3)) -> ± 0
A38: =A37+1 -> 36 | B38: 38 | C38: 61080 | D38: =POWER(C38/($O$5-1),0.5) -> 45.89343 | E38: =B38+3*D38 -> 175.68029 | F38: =B38-3*D38 -> -99.680289 | G38: =D38/B38*100 -> 120.77218 | H38: =D38/POWER($O$5, 0.5) -> 8.3789556 | I38: =H38*$P$5 -> 16.757911 | J38: =I38/B38*100 -> 44.099766 | K38: =ROUNDUP(POWER(G38*$P$5/$Q$5,2),0) -> 2334 | L38: =B38 & " ± " & (ROUNDUP(I38, 3)) -> 38 ± 16,758
A39: =A38+1 -> 37 | D39: =POWER(C39/($O$5-1),0.5) -> 0 | E39: =B39+3*D39 -> 0 | F39: =B39-3*D39 -> 0 | G39: =D39/B39*100 -> #DIV/0! | H39: =D39/POWER($O$5, 0.5) -> 0 | I39: =H39*$P$5 -> 0 | J39: =I39/B39*100 -> #DIV/0! | K39: =ROUNDUP(POWER(G39*$P$5/$Q$5,2),0) -> #DIV/0! | L39: =B39 & " ± " & (ROUNDUP(I39, 3)) -> ± 0
A40: =A39+1 -> 38 | D40: =POWER(C40/($O$5-1),0.5) -> 0 | E40: =B40+3*D40 -> 0 | F40: =B40-3*D40 -> 0 | G40: =D40/B40*100 -> #DIV/0! | H40: =D40/POWER($O$5, 0.5) -> 0 | I40: =H40*$P$5 -> 0 | J40: =I40/B40*100 -> #DIV/0! | K40: =ROUNDUP(POWER(G40*$P$5/$Q$5,2),0) -> #DIV/0! | L40: =B40 & " ± " & (ROUNDUP(I40, 3)) -> ± 0
A41: =A40+1 -> 39 | D41: =POWER(C41/($O$5-1),0.5) -> 0 | E41: =B41+3*D41 -> 0 | F41: =B41-3*D41 -> 0 | G41: =D41/B41*100 -> #DIV/0! | H41: =D41/POWER($O$5, 0.5) -> 0 | I41: =H41*$P$5 -> 0 | J41: =I41/B41*100 -> #DIV/0! | K41: =ROUNDUP(POWER(G41*$P$5/$Q$5,2),0) -> #DIV/0! | L41: =B41 & " ± " & (ROUNDUP(I41, 3)) -> ± 0
...

Sheet l_12
A1: Серия экспериментов\статистика | B1: l_ср [1/м.е.] | C1: Σ((Δli)^2) [1/м.е.^2] | D1: σ [1/м.е.] | E1: l_ср+3*σ [1/м.е.] | F1: l_ср-3*σ [1/м.е.] | G1: kв [%] | H1: σ0 [1/м.е.] | I1: Δl [1/м.е.] | J1: δl [%] | K1: N_мин | L1: l_ист [1/м.е.]
A3: 1 | B3: 0 | C3: 0 | D3: =POWER(C3/($O$5-1),0.5) -> 0 | E3: =B3+3*D3 -> 0 | F3: =B3-3*D3 -> 0 | G3: =D3/B3*100 -> #DIV/0! | H3: =D3/POWER($O$5, 0.5) -> 0 | I3: =H3*$P$5 -> 0 | J3: =I3/B3*100 -> #DIV/0! | K3: =ROUNDUP(POWER(G3*$P$5/$Q$5,2),0) -> #DIV/0! | L3: =B3 & " ± " & (ROUNDUP(I3, 3)) -> 0 ± 0
A4: =A3+1 -> 2 | D4: =POWER(C4/($O$5-1),0.5) -> 0 | E4: =B4+3*D4 -> 0 | F4: =B4-3*D4 -> 0 | G4: =D4/B4*100 -> #DIV/0! | H4: =D4/POWER($O$5, 0.5) -> 0 | I4: =H4*$P$5 -> 0 | J4: =I4/B4*100 -> #DIV/0! | K4: =ROUNDUP(POWER(G4*$P$5/$Q$5,2),0) -> #DIV/0! | L4: =B4 & " ± " & (ROUNDUP(I4, 3)) -> ± 0 | N4: p | O4: N | P4: t_pN | Q4: Δ [%]
A5: =A4+1 -> 3 | D5: =POWER(C5/($O$5-1),0.5) -> 0 | E5: =B5+3*D5 -> 0 | F5: =B5-3*D5 -> 0 | G5: =D5/B5*100 -> #DIV/0! | H5: =D5/POWER($O$5, 0.5) -> 0 | I5: =H5*$P$5 -> 0 | J5: =I5/B5*100 -> #DIV/0! | K5: =ROUNDUP(POWER(G5*$P$5/$Q$5,2),0) -> #DIV/0! | L5: =B5 & " ± " & (ROUNDUP(I5, 3)) -> ± 0 | N5: 0.95 | O5: 30 | P5: 2 | Q5: 5
A6: =A5+1 -> 4 | D6: =POWER(C6/($O$5-1),0.5) -> 0 | E6: =B6+3*D6 -> 0 | F6: =B6-3*D6 -> 0 | G6: =D6/B6*100 -> #DIV/0! | H6: =D6/POWER($O$5, 0.5) -> 0 | I6: =H6*$P$5 -> 0 | J6: =I6/B6*100 -> #DIV/0! | K6: =ROUNDUP(POWER(G6*$P$5/$Q$5,2),0) -> #DIV/0! | L6: =B6 & " ± " & (ROUNDUP(I6, 3)) -> ± 0
A7: =A6+1 -> 5 | D7: =POWER(C7/($O$5-1),0.5) -> 0 | E7: =B7+3*D7 -> 0 | F7: =B7-3*D7 -> 0 | G7: =D7/B7*100 -> #DIV/0! | H7: =D7/POWER($O$5, 0.5) -> 0 | I7: =H7*$P$5 -> 0 | J7: =I7/B7*100 -> #DIV/0! | K7: =ROUNDUP(POWER(G7*$P$5/$Q$5,2),0) -> #DIV/0! | L7: =B7 & " ± " & (ROUNDUP(I7, 3)) -> ± 0
A8: =A7+1 -> 6 | B8: 9.75e-07 | C8: 0 | D8: =POWER(C8/($O$5-1),0.5) -> 0 | E8: =B8+3*D8 -> 9.75e-07 | F8: =B8-3*D8 -> 9.75e-07 | G8: =D8/B8*100 -> 0 | H8: =D8/POWER($O$5, 0.5) -> 0 | I8: =H8*$P$5 -> 0 | J8: =I8/B8*100 -> 0 | K8: =ROUNDUP(POWER(G8*$P$5/$Q$5,2),0) -> 0 | L8: =B8 & " ± " & (ROUNDUP(I8, 3)) -> 0,000000975 ± 0
A9: =A8+1 -> 7 | D9: =POWER(C9/($O$5-1),0.5) -> 0 | E9: =B9+3*D9 -> 0 | F9: =B9-3*D9 -> 0 | G9: =D9/B9*100 -> #DIV/0! | H9: =D9/POWER($O$5, 0.5) -> 0 | I9: =H9*$P$5 -> 0 | J9: =I9/B9*100 -> #DIV/0! | K9: =ROUNDUP(POWER(G9*$P$5/$Q$5,2),0) -> #DIV/0! | L9: =B9 & " ± " & (ROUNDUP(I9, 3)) -> ± 0
A10: =A9+1 -> 8 | D10: =POWER(C10/($O$5-1),0.5) -> 0 | E10: =B10+3*D10 -> 0 | F10: =B10-3*D10 -> 0 | G10: =D10/B10*100 -> #DIV/0! | H10: =D10/POWER($O$5, 0.5) -> 0 | I10: =H10*$P$5 -> 0 | J10: =I10/B10*100 -> #DIV/0! | K10: =ROUNDUP(POWER(G10*$P$5/$Q$5,2),0) -> #DIV/0! | L10: =B10 & " ± " & (ROUNDUP(I10, 3)) -> ± 0
A11: =A10+1 -> 9 | D11: =POWER(C11/($O$5-1),0.5) -> 0 | E11: =B11+3*D11 -> 0 | F11: =B11-3*D11 -> 0 | G11: =D11/B11*100 -> #DIV/0! | H11: =D11/POWER($O$5, 0.5) -> 0 | I11: =H11*$P$5 -> 0 | J11: =I11/B11*100 -> #DIV/0! | K11: =ROUNDUP(POWER(G11*$P$5/$Q$5,2),0) -> #DIV/0! | L11: =B11 & " ± " & (ROUNDUP(I11, 3)) -> ± 0
A12: =A11+1 -> 10 | D12: =POWER(C12/($O$5-1),0.5) -> 0 | E12: =B12+3*D12 -> 0 | F12: =B12-3*D12 -> 0 | G12: =D12/B12*100 -> #DIV/0! | H12: =D12/POWER($O$5, 0.5) -> 0 | I12: =H12*$P$5 -> 0 | J12: =I12/B12*100 -> #DIV/0! | K12: =ROUNDUP(POWER(G12*$P$5/$Q$5,2),0) -> #DIV/0! | L12: =B12 & " ± " & (ROUNDUP(I12, 3)) -> ± 0
A13: =A12+1 -> 11 | B13: 0 | C13: 0 | D13: =POWER(C13/($O$5-1),0.5) -> 0 | E13: =B13+3*D13 -> 0 | F13: =B13-3*D13 -> 0 | G13: =D13/B13*100 -> #DIV/0! | H13: =D13/POWER($O$5, 0.5) -> 0 | I13: =H13*$P$5 -> 0 | J13: =I13/B13*100 -> #DIV/0! | K13: =ROUNDUP(POWER(G13*$P$5/$Q$5,2),0) -> #DIV/0! | L13: =B13 & " ± " & (ROUNDUP(I13, 3)) -> 0 ± 0
A14: =A13+1 -> 12 | D14: =POWER(C14/($O$5-1),0.5) -> 0 | E14: =B14+3*D14 -> 0 | F14: =B14-3*D14 -> 0 | G14: =D14/B14*100 -> #DIV/0! | H14: =D14/POWER($O$5, 0.5) -> 0 | I14: =H14*$P$5 -> 0 | J14: =I14/B14*100 -> #DIV/0! | K14: =ROUNDUP(POWER(G14*$P$5/$Q$5,2),0) -> #DIV/0! | L14: =B14 & " ± " & (ROUNDUP(I14, 3)) -> ± 0
A15: =A14+1 -> 13 | D15: =POWER(C15/($O$5-1),0.5) -> 0 | E15: =B15+3*D15 -> 0 | F15: =B15-3*D15 -> 0 | G15: =D15/B15*100 -> #DIV/0! | H15: =D15/POWER($O$5, 0.5) -> 0 | I15: =H15*$P$5 -> 0 | J15: =I15/B15*100 -> #DIV/0! | K15: =ROUNDUP(POWER(G15*$P$5/$Q$5,2),0) -> #DIV/0! | L15: =B15 & " ± " & (ROUNDUP(I15, 3)) -> ± 0
A16: =A15+1 -> 14 | D16: =POWER(C16/($O$5-1),0.5) -> 0 | E16: =B16+3*D16 -> 0 | F16: =B16-3*D16 -> 0 | G16: =D16/B16*100 -> #DIV/0! | H16: =D16/POWER($O$5, 0.5) -> 0 | I16: =H16*$P$5 -> 0 | J16: =I16/B16*100 -> #DIV/0! | K16: =ROUNDUP(POWER(G16*$P$5/$Q$5,2),0) -> #DIV/0! | L16: =B16 & " ± " & (ROUNDUP(I16, 3)) -> ± 0
A17: =A16+1 -> 15 | D17: =POWER(C17/($O$5-1),0.5) -> 0 | E17: =B17+3*D17 -> 0 | F17: =B17-3*D17 -> 0 | G17: =D17/B17*100 -> #DIV/0! | H17: =D17/POWER($O$5, 0.5) -> 0 | I17: =H17*$P$5 -> 0 | J17: =I17/B17*100 -> #DIV/0! | K17: =ROUNDUP(POWER(G17*$P$5/$Q$5,2),0) -> #DIV/0! | L17: =B17 & " ± " & (ROUNDUP(I17, 3)) -> ± 0
A18: =A17+1 -> 16 | B18: 0.00028265 | C18: 2.48e-06 | D18: =POWER(C18/($O$5-1),0.5) -> 0.00029243331 | E18: =B18+3*D18 -> 0.0011599499 | F18: =B18-3*D18 -> -0.00059464993 | G18: =D18/B18*100 -> 103.46128 | H18: =D18/POWER($O$5, 0.5) -> 5.3390774e-05 | I18: =H18*$P$5 -> 0.00010678155 | J18: =I18/B18*100 -> 37.778718 | K18: =ROUNDUP(POWER(G18*$P$5/$Q$5,2),0) -> 1713 | L18: =B18 & " ± " & (ROUNDUP(I18, 3)) -> 0,00028265 ± 0,001
A19: =A18+1 -> 17 | D19: =POWER(C19/($O$5-1),0.5) -> 0 | E19: =B19+3*D19 -> 0 | F19: =B19-3*D19 -> 0 | G19: =D19/B19*100 -> #DIV/0! | H19: =D19/POWER($O$5, 0.5) -> 0 | I19: =H19*$P$5 -> 0 | J19: =I19/B19*100 -> #DIV/0! | K19: =ROUNDUP(POWER(G19*$P$5/$Q$5,2),0) -> #DIV/0! | L19: =B19 & " ± " & (ROUNDUP(I19, 3)) -> ± 0
A20: =A19+1 -> 18 | D20: =POWER(C20/($O$5-1),0.5) -> 0 | E20: =B20+3*D20 -> 0 | F20: =B20-3*D20 -> 0 | G20: =D20/B20*100 -> #DIV/0! | H20: =D20/POWER($O$5, 0.5) -> 0 | I20: =H20*$P$5 -> 0 | J20: =I20/B20*100 -> #DIV/0! | K20: =ROUNDUP(POWER(G20*$P$5/$Q$5,2),0) -> #DIV/0! | L20: =B20 & " ± " & (ROUNDUP(I20, 3)) -> ± 0
A21: =A20+1 -> 19 | D21: =POWER(C21/($O$5-1),0.5) -> 0 | E21: =B21+3*D21 -> 0 | F21: =B21-3*D21 -> 0 | G21: =D21/B21*100 -> #DIV/0! | H21: =D21/POWER($O$5, 0.5) -> 0 | I21: =H21*$P$5 -> 0 | J21: =I21/B21*100 -> #DIV/0! | K21: =ROUNDUP(POWER(G21*$P$5/$Q$5,2),0) -> #DIV/0! | L21: =B21 & " ± " & (ROUNDUP(I21, 3)) -> ± 0
A22: =A21+1 -> 20 | D22: =POWER(C22/($O$5-1),0.5) -> 0 | E22: =B22+3*D22 -> 0 | F22: =B22-3*D22 -> 0 | G22: =D22/B22*100 -> #DIV/0! | H22: =D22/POWER($O$5, 0.5) -> 0 | I22: =H22*$P$5 -> 0 | J22: =I22/B22*100 -> #DIV/0! | K22: =ROUNDUP(POWER(G22*$P$5/$Q$5,2),0) -> #DIV/0! | L22: =B22 & " ± " & (ROUNDUP(I22, 3)) -> ± 0
A23: =A22+1 -> 21 | B23: 8.772e-05 | C23: 7.1e-07 | D23: =POWER(C23/($O$5-1),0.5) -> 0.00015646967 | E23: =B23+3*D23 -> 0.00055712902 | F23: =B23-3*D23 -> -0.00038168902 | G23: =D23/B23*100 -> 178.374 | H23: =D23/POWER($O$5, 0.5) -> 2.8567323e-05 | I23: =H23*$P$5 -> 5.7134646e-05 | J23: =I23/B23*100 -> 65.132976 | K23: =ROUNDUP(POWER(G23*$P$5/$Q$5,2),0) -> 5091 | L23: =B23 & " ± " & (ROUNDUP(I23, 3)) -> 0,00008772 ± 0,001
A24: =A23+1 -> 22 | D24: =POWER(C24/($O$5-1),0.5) -> 0 | E24: =B24+3*D24 -> 0 | F24: =B24-3*D24 -> 0 | G24: =D24/B24*100 -> #DIV/0! | H24: =D24/POWER($O$5, 0.5) -> 0 | I24: =H24*$P$5 -> 0 | J24: =I24/B24*100 -> #DIV/0! | K24: =ROUNDUP(POWER(G24*$P$5/$Q$5,2),0) -> #DIV/0! | L24: =B24 & " ± " & (ROUNDUP(I24, 3)) -> ± 0
